Workbook

Sheet Dashboard
B1: CONTROL DE GASTOS PERSONALES 2025
B2: ="Actualizado: "&TEXT(NOW(),"DD/MM/YYYY") -> #ERROR!
B4: Seleccionar Mes: | D4: Enero
B6: INGRESOS | D6: GASTOS | F6: BALANCE | H6: % AHORRO
B7: =IFERROR(INDIRECT("'"&D4&"'!E3"),0) -> #ERROR! | D7: =IFERROR(SUM(INDIRECT("'"&D4&"'!F6:F55")),0) -> #ERROR! | F7: =G7-I7 -> 0 | H7: =IFERROR(K7/G7*100,"")
B9: RESUMEN POR PERSONA
B10: Persona | D10: Ingresos | F10: Gastos | H10: Balance | J10: % Gasto Total
B11: MAURO | D11: =IFERROR(INDIRECT("'"&D4&"'!C3"),0) -> #ERROR! | F11: =IFERROR(SUMIFS(INDIRECT("'"&D4&"'!F:F"),INDIRECT("'"&D4&"'!C:C"),"Franco"),0) -> #ERROR! | H11: =D11-F11 -> #ERROR! | J11: =IFERROR(F11/I7*100,"")
B12: DAIANA | D12: =IFERROR(INDIRECT("'"&D4&"'!D3"),0) -> #ERROR! | F12: =IFERROR(SUMIFS(INDIRECT("'"&D4&"'!F:F"),INDIRECT("'"&D4&"'!C:C"),"Pareja"),0) -> #ERROR! | H12: =D12-F12 -> #ERROR! | J12: =IFERROR(F12/I7*100,"")
B14: GASTOS POR CATEGORIA DEL MES | I14: FORMA DE PAGO
B15: Categoria | D15: Monto | F15: % | I15: Forma | K15: Monto
B16: Alimentación | D16: =IFERROR(SUMIFS(INDIRECT("'"&D4&"'!F:F"),INDIRECT("'"&D4&"'!E:E"),"Alimentación"),0) -> #ERROR! | F16: =IFERROR(D16/I7*100,"") | I16: Efectivo | K16: =IFERROR(SUMIFS(INDIRECT("'"&D4&"'!F:F"),INDIRECT("'"&D4&"'!G:G"),"Efectivo"),0) -> #ERROR!
B17: Transporte | D17: =IFERROR(SUMIFS(INDIRECT("'"&D4&"'!F:F"),INDIRECT("'"&D4&"'!E:E"),"Transporte"),0) -> #ERROR! | F17: =IFERROR(D17/I7*100,"") | I17: Tarjeta Debito | K17: =IFERROR(SUMIFS(INDIRECT("'"&D4&"'!F:F"),INDIRECT("'"&D4&"'!G:G"),"Tarjeta Debito"),0) -> #ERROR!
B18: Vivienda | D18: =IFERROR(SUMIFS(INDIRECT("'"&D4&"'!F:F"),INDIRECT("'"&D4&"'!E:E"),"Vivienda"),0) -> #ERROR! | F18: =IFERROR(D18/I7*100,"") | I18: Tarjeta Credito | K18: =IFERROR(SUMIFS(INDIRECT("'"&D4&"'!F:F"),INDIRECT("'"&D4&"'!G:G"),"Tarjeta Credito"),0) -> #ERROR!
B19: Salud | D19: =IFERROR(SUMIFS(INDIRECT("'"&D4&"'!F:F"),INDIRECT("'"&D4&"'!E:E"),"Salud"),0) -> #ERROR! | F19: =IFERROR(D19/I7*100,"") | I19: Transferencia | K19: =IFERROR(SUMIFS(INDIRECT("'"&D4&"'!F:F"),INDIRECT("'"&D4&"'!G:G"),"Transferencia"),0) -> #ERROR!
B20: Educación | D20: =IFERROR(SUMIFS(INDIRECT("'"&D4&"'!F:F"),INDIRECT("'"&D4&"'!E:E"),"Educación"),0) -> #ERROR! | F20: =IFERROR(D20/I7*100,"")
B21: Entretenimiento | D21: =IFERROR(SUMIFS(INDIRECT("'"&D4&"'!F:F"),INDIRECT("'"&D4&"'!E:E"),"Entretenimiento"),0) -> #ERROR! | F21: =IFERROR(D21/I7*100,"")
B22: Ropa | D22: =IFERROR(SUMIFS(INDIRECT("'"&D4&"'!F:F"),INDIRECT("'"&D4&"'!E:E"),"Ropa"),0) -> #ERROR! | F22: =IFERROR(D22/I7*100,"")
B23: Servicios | D23: =IFERROR(SUMIFS(INDIRECT("'"&D4&"'!F:F"),INDIRECT("'"&D4&"'!E:E"),"Servicios"),0) -> #ERROR! | F23: =IFERROR(D23/I7*100,"")
B24: Ahorro | D24: =IFERROR(SUMIFS(INDIRECT("'"&D4&"'!F:F"),INDIRECT("'"&D4&"'!E:E"),"Ahorro"),0) -> #ERROR! | F24: =IFERROR(D24/I7*100,"")
B25: Otros | D25: =IFERROR(SUMIFS(INDIRECT("'"&D4&"'!F:F"),INDIRECT("'"&D4&"'!E:E"),"Otros"),0) -> #ERROR! | F25: =IFERROR(D25/I7*100,"")

Sheet Resumen Anual
B1: RESUMEN ANUAL 2025
B3: Concepto | C3: ENE | D3: FEB | E3: MAR | F3: ABR | G3: MAY | H3: JUN | I3: JUL | J3: AGO | K3: SEP | L3: OCT | M3: NOV | N3: DIC | O3: TOTAL | P3: PROM | Q3: MAX
B4: Ingresos Franco | C4: =IFERROR('Enero'!C3,0) -> #ERROR! | D4: =IFERROR('Febrero'!C3,0) -> #ERROR! | E4: =IFERROR('Marzo'!C3,0) -> #ERROR! | F4: =IFERROR('Abril'!C3,0) -> #ERROR! | G4: =IFERROR('Mayo'!C3,0) -> #ERROR! | H4: =IFERROR('Junio'!C3,0) -> #ERROR! | I4: =IFERROR('Julio'!C3,0) -> #ERROR! | J4: =IFERROR('Agosto'!C3,0) -> #ERROR! | K4: =IFERROR('Septiembre'!C3,0) -> #ERROR! | L4: =IFERROR('Octubre'!C3,0) -> #ERROR! | M4: =IFERROR('Noviembre'!C3,0) -> #ERROR! | N4: =IFERROR('Diciembre'!C3,0) -> #ERROR! | O4: =SUM(C4:N4) -> #ERROR! | P4: =AVERAGE(C4:N4) -> #ERROR! | Q4: =MAX(C4:N4) -> #ERROR!
B5: Ingresos Pareja | C5: =IFERROR('Enero'!D3,0) -> #ERROR! | D5: =IFERROR('Febrero'!D3,0) -> #ERROR! | E5: =IFERROR('Marzo'!D3,0) -> #ERROR! | F5: =IFERROR('Abril'!D3,0) -> #ERROR! | G5: =IFERROR('Mayo'!D3,0) -> #ERROR! | H5: =IFERROR('Junio'!D3,0) -> #ERROR! | I5: =IFERROR('Julio'!D3,0) -> #ERROR! | J5: =IFERROR('Agosto'!D3,0) -> #ERROR! | K5: =IFERROR('Septiembre'!D3,0) -> #ERROR! | L5: =IFERROR('Octubre'!D3,0) -> #ERROR! | M5: =IFERROR('Noviembre'!D3,0) -> #ERROR! | N5: =IFERROR('Diciembre'!D3,0) -> #ERROR! | O5: =SUM(C5:N5) -> #ERROR! | P5: =AVERAGE(C5:N5) -> #ERROR! | Q5: =MAX(C5:N5) -> #ERROR!
B6: TOTAL INGRESOS | C6: =IFERROR('Enero'!E3,0) -> #ERROR! | D6: =IFERROR('Febrero'!E3,0) -> #ERROR! | E6: =IFERROR('Marzo'!E3,0) -> #ERROR! | F6: =IFERROR('Abril'!E3,0) -> #ERROR! | G6: =IFERROR('Mayo'!E3,0) -> #ERROR! | H6: =IFERROR('Junio'!E3,0) -> #ERROR! | I6: =IFERROR('Julio'!E3,0) -> #ERROR! | J6: =IFERROR('Agosto'!E3,0) -> #ERROR! | K6: =IFERROR('Septiembre'!E3,0) -> #ERROR! | L6: =IFERROR('Octubre'!E3,0) -> #ERROR! | M6: =IFERROR('Noviembre'!E3,0) -> #ERROR! | N6: =IFERROR('Diciembre'!E3,0) -> #ERROR! | O6: =SUM(C6:N6) -> #ERROR! | P6: =AVERAGE(C6:N6) -> #ERROR! | Q6: =MAX(C6:N6) -> #ERROR!
B7: TOTAL GASTOS | C7: =IFERROR(SUM('Enero'!F6:F55),0) -> #ERROR! | D7: =IFERROR(SUM('Febrero'!F6:F55),0) -> #ERROR! | E7: =IFERROR(SUM('Marzo'!F6:F55),0) -> #ERROR! | F7: =IFERROR(SUM('Abril'!F6:F55),0) -> #ERROR! | G7: =IFERROR(SUM('Mayo'!F6:F55),0) -> #ERROR! | H7: =IFERROR(SUM('Junio'!F6:F55),0) -> #ERROR! | I7: =IFERROR(SUM('Julio'!F6:F55),0) -> #ERROR! | J7: =IFERROR(SUM('Agosto'!F6:F55),0) -> #ERROR! | K7: =IFERROR(SUM('Septiembre'!F6:F55),0) -> #ERROR! | L7: =IFERROR(SUM('Octubre'!F6:F55),0) -> #ERROR! | M7: =IFERROR(SUM('Noviembre'!F6:F55),0) -> #ERROR! | N7: =IFERROR(SUM('Diciembre'!F6:F55),0) -> #ERROR! | O7: =SUM(C7:N7) -> #ERROR! | P7: =AVERAGE(C7:N7) -> #ERROR! | Q7: =MAX(C7:N7) -> #ERROR!
B8: BALANCE | C8: =IFERROR('Enero'!E3-SUM('Enero'!F6:F55),0) -> #ERROR! | D8: =IFERROR('Febrero'!E3-SUM('Febrero'!F6:F55),0) -> #ERROR! | E8: =IFERROR('Marzo'!E3-SUM('Marzo'!F6:F55),0) -> #ERROR! | F8: =IFERROR('Abril'!E3-SUM('Abril'!F6:F55),0) -> #ERROR! | G8: =IFERROR('Mayo'!E3-SUM('Mayo'!F6:F55),0) -> #ERROR! | H8: =IFERROR('Junio'!E3-SUM('Junio'!F6:F55),0) -> #ERROR! | I8: =IFERROR('Julio'!E3-SUM('Julio'!F6:F55),0) -> #ERROR! | J8: =IFERROR('Agosto'!E3-SUM('Agosto'!F6:F55),0) -> #ERROR! | K8: =IFERROR('Septiembre'!E3-SUM('Septiembre'!F6:F55),0) -> #ERROR! | L8: =IFERROR('Octubre'!E3-SUM('Octubre'!F6:F55),0) -> #ERROR! | M8: =IFERROR('Noviembre'!E3-SUM('Noviembre'!F6:F55),0) -> #ERROR! | N8: =IFERROR('Diciembre'!E3-SUM('Diciembre'!F6:F55),0) -> #ERROR! | O8: =SUM(C8:N8) -> #ERROR! | P8: =AVERAGE(C8:N8) -> #ERROR! | Q8: =MAX(C8:N8) -> #ERROR!
B9: AHORRO | C9: =IFERROR(MAX('Enero'!E3-SUM('Enero'!F6:F55),0),0) -> #ERROR! | D9: =IFERROR(MAX('Febrero'!E3-SUM('Febrero'!F6:F55),0),0) -> #ERROR! | E9: =IFERROR(MAX('Marzo'!E3-SUM('Marzo'!F6:F55),0),0) -> #ERROR! | F9: =IFERROR(MAX('Abril'!E3-SUM('Abril'!F6:F55),0),0) -> #ERROR! | G9: =IFERROR(MAX('Mayo'!E3-SUM('Mayo'!F6:F55),0),0) -> #ERROR! | H9: =IFERROR(MAX('Junio'!E3-SUM('Junio'!F6:F55),0),0) -> #ERROR! | I9: =IFERROR(MAX('Julio'!E3-SUM('Julio'!F6:F55),0),0) -> #ERROR! | J9: =IFERROR(MAX('Agosto'!E3-SUM('Agosto'!F6:F55),0),0) -> #ERROR! | K9: =IFERROR(MAX('Septiembre'!E3-SUM('Septiembre'!F6:F55),0),0) -> #ERROR! | L9: =IFERROR(MAX('Octubre'!E3-SUM('Octubre'!F6:F55),0),0) -> #ERROR! | M9: =IFERROR(MAX('Noviembre'!E3-SUM('Noviembre'!F6:F55),0),0) -> #ERROR! | N9: =IFERROR(MAX('Diciembre'!E3-SUM('Diciembre'!F6:F55),0),0) -> #ERROR! | O9: =SUM(C9:N9) -> #ERROR! | P9: =AVERAGE(C9:N9) -> #ERROR! | Q9: =MAX(C9:N9) -> #ERROR!
B11: GASTOS POR CATEGORIA (ANUAL)
B12: Alimentación | C12: =IFERROR(SUMIF('Enero'!E6:E55,"Alimentación",'Enero'!F6:F55),0) -> #ERROR! | D12: =IFERROR(SUMIF('Febrero'!E6:E55,"Alimentación",'Febrero'!F6:F55),0) -> #ERROR! | E12: =IFERROR(SUMIF('Marzo'!E6:E55,"Alimentación",'Marzo'!F6:F55),0) -> #ERROR! | F12: =IFERROR(SUMIF('Abril'!E6:E55,"Alimentación",'Abril'!F6:F55),0) -> #ERROR! | G12: =IFERROR(SUMIF('Mayo'!E6:E55,"Alimentación",'Mayo'!F6:F55),0) -> #ERROR! | H12: =IFERROR(SUMIF('Junio'!E6:E55,"Alimentación",'Junio'!F6:F55),0) -> #ERROR! | I12: =IFERROR(SUMIF('Julio'!E6:E55,"Alimentación",'Julio'!F6:F55),0) -> #ERROR! | J12: =IFERROR(SUMIF('Agosto'!E6:E55,"Alimentación",'Agosto'!F6:F55),0) -> #ERROR! | K12: =IFERROR(SUMIF('Septiembre'!E6:E55,"Alimentación",'Septiembre'!F6:F55),0) -> #ERROR! | L12: =IFERROR(SUMIF('Octubre'!E6:E55,"Alimentación",'Octubre'!F6:F55),0) -> #ERROR! | M12: =IFERROR(SUMIF('Noviembre'!E6:E55,"Alimentación",'Noviembre'!F6:F55),0) -> #ERROR! | N12: =IFERROR(SUMIF('Diciembre'!E6:E55,"Alimentación",'Diciembre'!F6:F55),0) -> #ERROR! | O12: =SUM(C12:N12) -> #ERROR! | P12: =AVERAGE(C12:N12) -> #ERROR! | Q12: =MAX(C12:N12) -> #ERROR!
B13: Transporte | C13: =IFERROR(SUMIF('Enero'!E6:E55,"Transporte",'Enero'!F6:F55),0) -> #ERROR! | D13: =IFERROR(SUMIF('Febrero'!E6:E55,"Transporte",'Febrero'!F6:F55),0) -> #ERROR! | E13: =IFERROR(SUMIF('Marzo'!E6:E55,"Transporte",'Marzo'!F6:F55),0) -> #ERROR! | F13: =IFERROR(SUMIF('Abril'!E6:E55,"Transporte",'Abril'!F6:F55),0) -> #ERROR! | G13: =IFERROR(SUMIF('Mayo'!E6:E55,"Transporte",'Mayo'!F6:F55),0) -> #ERROR! | H13: =IFERROR(SUMIF('Junio'!E6:E55,"Transporte",'Junio'!F6:F55),0) -> #ERROR! | I13: =IFERROR(SUMIF('Julio'!E6:E55,"Transporte",'Julio'!F6:F55),0) -> #ERROR! | J13: =IFERROR(SUMIF('Agosto'!E6:E55,"Transporte",'Agosto'!F6:F55),0) -> #ERROR! | K13: =IFERROR(SUMIF('Septiembre'!E6:E55,"Transporte",'Septiembre'!F6:F55),0) -> #ERROR! | L13: =IFERROR(SUMIF('Octubre'!E6:E55,"Transporte",'Octubre'!F6:F55),0) -> #ERROR! | M13: =IFERROR(SUMIF('Noviembre'!E6:E55,"Transporte",'Noviembre'!F6:F55),0) -> #ERROR! | N13: =IFERROR(SUMIF('Diciembre'!E6:E55,"Transporte",'Diciembre'!F6:F55),0) -> #ERROR! | O13: =SUM(C13:N13) -> #ERROR! | P13: =AVERAGE(C13:N13) -> #ERROR! | Q13: =MAX(C13:N13) -> #ERROR!
B14: Vivienda | C14: =IFERROR(SUMIF('Enero'!E6:E55,"Vivienda",'Enero'!F6:F55),0) -> #ERROR! | D14: =IFERROR(SUMIF('Febrero'!E6:E55,"Vivienda",'Febrero'!F6:F55),0) -> #ERROR! | E14: =IFERROR(SUMIF('Marzo'!E6:E55,"Vivienda",'Marzo'!F6:F55),0) -> #ERROR! | F14: =IFERROR(SUMIF('Abril'!E6:E55,"Vivienda",'Abril'!F6:F55),0) -> #ERROR! | G14: =IFERROR(SUMIF('Mayo'!E6:E55,"Vivienda",'Mayo'!F6:F55),0) -> #ERROR! | H14: =IFERROR(SUMIF('Junio'!E6:E55,"Vivienda",'Junio'!F6:F55),0) -> #ERROR! | I14: =IFERROR(SUMIF('Julio'!E6:E55,"Vivienda",'Julio'!F6:F55),0) -> #ERROR! | J14: =IFERROR(SUMIF('Agosto'!E6:E55,"Vivienda",'Agosto'!F6:F55),0) -> #ERROR! | K14: =IFERROR(SUMIF('Septiembre'!E6:E55,"Vivienda",'Septiembre'!F6:F55),0) -> #ERROR! | L14: =IFERROR(SUMIF('Octubre'!E6:E55,"Vivienda",'Octubre'!F6:F55),0) -> #ERROR! | M14: =IFERROR(SUMIF('Noviembre'!E6:E55,"Vivienda",'Noviembre'!F6:F55),0) -> #ERROR! | N14: =IFERROR(SUMIF('Diciembre'!E6:E55,"Vivienda",'Diciembre'!F6:F55),0) -> #ERROR! | O14: =SUM(C14:N14) -> #ERROR! | P14: =AVERAGE(C14:N14) -> #ERROR! | Q14: =MAX(C14:N14) -> #ERROR!
B15: Salud | C15: =IFERROR(SUMIF('Enero'!E6:E55,"Salud",'Enero'!F6:F55),0) -> #ERROR! | D15: =IFERROR(SUMIF('Febrero'!E6:E55,"Salud",'Febrero'!F6:F55),0) -> #ERROR! | E15: =IFERROR(SUMIF('Marzo'!E6:E55,"Salud",'Marzo'!F6:F55),0) -> #ERROR! | F15: =IFERROR(SUMIF('Abril'!E6:E55,"Salud",'Abril'!F6:F55),0) -> #ERROR! | G15: =IFERROR(SUMIF('Mayo'!E6:E55,"Salud",'Mayo'!F6:F55),0) -> #ERROR! | H15: =IFERROR(SUMIF('Junio'!E6:E55,"Salud",'Junio'!F6:F55),0) -> #ERROR! | I15: =IFERROR(SUMIF('Julio'!E6:E55,"Salud",'Julio'!F6:F55),0) -> #ERROR! | J15: =IFERROR(SUMIF('Agosto'!E6:E55,"Salud",'Agosto'!F6:F55),0) -> #ERROR! | K15: =IFERROR(SUMIF('Septiembre'!E6:E55,"Salud",'Septiembre'!F6:F55),0) -> #ERROR! | L15: =IFERROR(SUMIF('Octubre'!E6:E55,"Salud",'Octubre'!F6:F55),0) -> #ERROR! | M15: =IFERROR(SUMIF('Noviembre'!E6:E55,"Salud",'Noviembre'!F6:F55),0) -> #ERROR! | N15: =IFERROR(SUMIF('Diciembre'!E6:E55,"Salud",'Diciembre'!F6:F55),0) -> #ERROR! | O15: =SUM(C15:N15) -> #ERROR! | P15: =AVERAGE(C15:N15) -> #ERROR! | Q15: =MAX(C15:N15) -> #ERROR!
B16: Educación | C16: =IFERROR(SUMIF('Enero'!E6:E55,"Educación",'Enero'!F6:F55),0) -> #ERROR! | D16: =IFERROR(SUMIF('Febrero'!E6:E55,"Educación",'Febrero'!F6:F55),0) -> #ERROR! | E16: =IFERROR(SUMIF('Marzo'!E6:E55,"Educación",'Marzo'!F6:F55),0) -> #ERROR! | F16: =IFERROR(SUMIF('Abril'!E6:E55,"Educación",'Abril'!F6:F55),0) -> #ERROR! | G16: =IFERROR(SUMIF('Mayo'!E6:E55,"Educación",'Mayo'!F6:F55),0) -> #ERROR! | H16: =IFERROR(SUMIF('Junio'!E6:E55,"Educación",'Junio'!F6:F55),0) -> #ERROR! | I16: =IFERROR(SUMIF('Julio'!E6:E55,"Educación",'Julio'!F6:F55),0) -> #ERROR! | J16: =IFERROR(SUMIF('Agosto'!E6:E55,"Educación",'Agosto'!F6:F55),0) -> #ERROR! | K16: =IFERROR(SUMIF('Septiembre'!E6:E55,"Educación",'Septiembre'!F6:F55),0) -> #ERROR! | L16: =IFERROR(SUMIF('Octubre'!E6:E55,"Educación",'Octubre'!F6:F55),0) -> #ERROR! | M16: =IFERROR(SUMIF('Noviembre'!E6:E55,"Educación",'Noviembre'!F6:F55),0) -> #ERROR! | N16: =IFERROR(SUMIF('Diciembre'!E6:E55,"Educación",'Diciembre'!F6:F55),0) -> #ERROR! | O16: =SUM(C16:N16) -> #ERROR! | P16: =AVERAGE(C16:N16) -> #ERROR! | Q16: =MAX(C16:N16) -> #ERROR!
B17: Entretenimiento | C17: =IFERROR(SUMIF('Enero'!E6:E55,"Entretenimiento",'Enero'!F6:F55),0) -> #ERROR! | D17: =IFERROR(SUMIF('Febrero'!E6:E55,"Entretenimiento",'Febrero'!F6:F55),0) -> #ERROR! | E17: =IFERROR(SUMIF('Marzo'!E6:E55,"Entretenimiento",'Marzo'!F6:F55),0) -> #ERROR! | F17: =IFERROR(SUMIF('Abril'!E6:E55,"Entretenimiento",'Abril'!F6:F55),0) -> #ERROR! | G17: =IFERROR(SUMIF('Mayo'!E6:E55,"Entretenimiento",'Mayo'!F6:F55),0) -> #ERROR! | H17: =IFERROR(SUMIF('Junio'!E6:E55,"Entretenimiento",'Junio'!F6:F55),0) -> #ERROR! | I17: =IFERROR(SUMIF('Julio'!E6:E55,"Entretenimiento",'Julio'!F6:F55),0) -> #ERROR! | J17: =IFERROR(SUMIF('Agosto'!E6:E55,"Entretenimiento",'Agosto'!F6:F55),0) -> #ERROR! | K17: =IFERROR(SUMIF('Septiembre'!E6:E55,"Entretenimiento",'Septiembre'!F6:F55),0) -> #ERROR! | L17: =IFERROR(SUMIF('Octubre'!E6:E55,"Entretenimiento",'Octubre'!F6:F55),0) -> #ERROR! | M17: =IFERROR(SUMIF('Noviembre'!E6:E55,"Entretenimiento",'Noviembre'!F6:F55),0) -> #ERROR! | N17: =IFERROR(SUMIF('Diciembre'!E6:E55,"Entretenimiento",'Diciembre'!F6:F55),0) -> #ERROR! | O17: =SUM(C17:N17) -> #ERROR! | P17: =AVERAGE(C17:N17) -> #ERROR! | Q17: =MAX(C17:N17) -> #ERROR!
B18: Ropa | C18: =IFERROR(SUMIF('Enero'!E6:E55,"Ropa",'Enero'!F6:F55),0) -> #ERROR! | D18: =IFERROR(SUMIF('Febrero'!E6:E55,"Ropa",'Febrero'!F6:F55),0) -> #ERROR! | E18: =IFERROR(SUMIF('Marzo'!E6:E55,"Ropa",'Marzo'!F6:F55),0) -> #ERROR! | F18: =IFERROR(SUMIF('Abril'!E6:E55,"Ropa",'Abril'!F6:F55),0) -> #ERROR! | G18: =IFERROR(SUMIF('Mayo'!E6:E55,"Ropa",'Mayo'!F6:F55),0) -> #ERROR! | H18: =IFERROR(SUMIF('Junio'!E6:E55,"Ropa",'Junio'!F6:F55),0) -> #ERROR! | I18: =IFERROR(SUMIF('Julio'!E6:E55,"Ropa",'Julio'!F6:F55),0) -> #ERROR! | J18: =IFERROR(SUMIF('Agosto'!E6:E55,"Ropa",'Agosto'!F6:F55),0) -> #ERROR! | K18: =IFERROR(SUMIF('Septiembre'!E6:E55,"Ropa",'Septiembre'!F6:F55),0) -> #ERROR! | L18: =IFERROR(SUMIF('Octubre'!E6:E55,"Ropa",'Octubre'!F6:F55),0) -> #ERROR! | M18: =IFERROR(SUMIF('Noviembre'!E6:E55,"Ropa",'Noviembre'!F6:F55),0) -> #ERROR! | N18: =IFERROR(SUMIF('Diciembre'!E6:E55,"Ropa",'Diciembre'!F6:F55),0) -> #ERROR! | O18: =SUM(C18:N18) -> #ERROR! | P18: =AVERAGE(C18:N18) -> #ERROR! | Q18: =MAX(C18:N18) -> #ERROR!
B19: Servicios | C19: =IFERROR(SUMIF('Enero'!E6:E55,"Servicios",'Enero'!F6:F55),0) -> #ERROR! | D19: =IFERROR(SUMIF('Febrero'!E6:E55,"Servicios",'Febrero'!F6:F55),0) -> #ERROR! | E19: =IFERROR(SUMIF('Marzo'!E6:E55,"Servicios",'Marzo'!F6:F55),0) -> #ERROR! | F19: =IFERROR(SUMIF('Abril'!E6:E55,"Servicios",'Abril'!F6:F55),0) -> #ERROR! | G19: =IFERROR(SUMIF('Mayo'!E6:E55,"Servicios",'Mayo'!F6:F55),0) -> #ERROR! | H19: =IFERROR(SUMIF('Junio'!E6:E55,"Servicios",'Junio'!F6:F55),0) -> #ERROR! | I19: =IFERROR(SUMIF('Julio'!E6:E55,"Servicios",'Julio'!F6:F55),0) -> #ERROR! | J19: =IFERROR(SUMIF('Agosto'!E6:E55,"Servicios",'Agosto'!F6:F55),0) -> #ERROR! | K19: =IFERROR(SUMIF('Septiembre'!E6:E55,"Servicios",'Septiembre'!F6:F55),0) -> #ERROR! | L19: =IFERROR(SUMIF('Octubre'!E6:E55,"Servicios",'Octubre'!F6:F55),0) -> #ERROR! | M19: =IFERROR(SUMIF('Noviembre'!E6:E55,"Servicios",'Noviembre'!F6:F55),0) -> #ERROR! | N19: =IFERROR(SUMIF('Diciembre'!E6:E55,"Servicios",'Diciembre'!F6:F55),0) -> #ERROR! | O19: =SUM(C19:N19) -> #ERROR! | P19: =AVERAGE(C19:N19) -> #ERROR! | Q19: =MAX(C19:N19) -> #ERROR!
B20: Ahorro | C20: =IFERROR(SUMIF('Enero'!E6:E55,"Ahorro",'Enero'!F6:F55),0) -> #ERROR! | D20: =IFERROR(SUMIF('Febrero'!E6:E55,"Ahorro",'Febrero'!F6:F55),0) -> #ERROR! | E20: =IFERROR(SUMIF('Marzo'!E6:E55,"Ahorro",'Marzo'!F6:F55),0) -> #ERROR! | F20: =IFERROR(SUMIF('Abril'!E6:E55,"Ahorro",'Abril'!F6:F55),0) -> #ERROR! | G20: =IFERROR(SUMIF('Mayo'!E6:E55,"Ahorro",'Mayo'!F6:F55),0) -> #ERROR! | H20: =IFERROR(SUMIF('Junio'!E6:E55,"Ahorro",'Junio'!F6:F55),0) -> #ERROR! | I20: =IFERROR(SUMIF('Julio'!E6:E55,"Ahorro",'Julio'!F6:F55),0) -> #ERROR! | J20: =IFERROR(SUMIF('Agosto'!E6:E55,"Ahorro",'Agosto'!F6:F55),0) -> #ERROR! | K20: =IFERROR(SUMIF('Septiembre'!E6:E55,"Ahorro",'Septiembre'!F6:F55),0) -> #ERROR! | L20: =IFERROR(SUMIF('Octubre'!E6:E55,"Ahorro",'Octubre'!F6:F55),0) -> #ERROR! | M20: =IFERROR(SUMIF('Noviembre'!E6:E55,"Ahorro",'Noviembre'!F6:F55),0) -> #ERROR! | N20: =IFERROR(SUMIF('Diciembre'!E6:E55,"Ahorro",'Diciembre'!F6:F55),0) -> #ERROR! | O20: =SUM(C20:N20) -> #ERROR! | P20: =AVERAGE(C20:N20) -> #ERROR! | Q20: =MAX(C20:N20) -> #ERROR!
B21: Otros | C21: =IFERROR(SUMIF('Enero'!E6:E55,"Otros",'Enero'!F6:F55),0) -> #ERROR! | D21: =IFERROR(SUMIF('Febrero'!E6:E55,"Otros",'Febrero'!F6:F55),0) -> #ERROR! | E21: =IFERROR(SUMIF('Marzo'!E6:E55,"Otros",'Marzo'!F6:F55),0) -> #ERROR! | F21: =IFERROR(SUMIF('Abril'!E6:E55,"Otros",'Abril'!F6:F55),0) -> #ERROR! | G21: =IFERROR(SUMIF('Mayo'!E6:E55,"Otros",'Mayo'!F6:F55),0) -> #ERROR! | H21: =IFERROR(SUMIF('Junio'!E6:E55,"Otros",'Junio'!F6:F55),0) -> #ERROR! | I21: =IFERROR(SUMIF('Julio'!E6:E55,"Otros",'Julio'!F6:F55),0) -> #ERROR! | J21: =IFERROR(SUMIF('Agosto'!E6:E55,"Otros",'Agosto'!F6:F55),0) -> #ERROR! | K21: =IFERROR(SUMIF('Septiembre'!E6:E55,"Otros",'Septiembre'!F6:F55),0) -> #ERROR! | L21: =IFERROR(SUMIF('Octubre'!E6:E55,"Otros",'Octubre'!F6:F55),0) -> #ERROR! | M21: =IFERROR(SUMIF('Noviembre'!E6:E55,"Otros",'Noviembre'!F6:F55),0) -> #ERROR! | N21: =IFERROR(SUMIF('Diciembre'!E6:E55,"Otros",'Diciembre'!F6:F55),0) -> #ERROR! | O21: =SUM(C21:N21) -> #ERROR! | P21: =AVERAGE(C21:N21) -> #ERROR! | Q21: =MAX(C21:N21) -> #ERROR!

Sheet Metas de Ahorro
B1: METAS DE AHORRO 2025
B2: Ingresa tus metas anuales. El ahorro real se calcula automaticamente desde las hojas mensuales.
B4: Persona | C4: Meta Anual | D4: Meta Mensual | E4: Ene | F4: Feb | G4: Mar | H4: Abr | I4: May | J4: Jun | K4: Jul | L4: Ago | M4: Sep | N4: Oct | O4: Nov | P4: Dic | Q4: Total | R4: %Cumpl
B5: MAURO | D5: =IFERROR(C5/12,"") -> 0 | E5: 0 | F5: 0 | G5: 0 | H5: 0 | I5: 0 | J5: 0 | K5: 0 | L5: 0 | M5: 0 | N5: 0 | O5: 0 | P5: 0 | Q5: =SUM(E5:P5) -> 0 | R5: =IFERROR(Q5/C5*100,"")
B6: DAIANA | D6: =IFERROR(C6/12,"") -> 0 | E6: 0 | F6: 0 | G6: 0 | H6: 500000 | I6: 0 | J6: 0 | K6: 0 | L6: 0 | M6: 0 | N6: 0 | O6: 0 | P6: 0 | Q6: =SUM(E6:P6) -> 500000 | R6: =IFERROR(Q6/C6*100,"")
B9: RESUMEN GLOBAL DEL HOGAR
B10: Meta Total Anual | F10: Total Ahorrado | J10: Cumplimiento % | N10: Falta para Meta
B11: =SUM(C5:C6) -> 0 | F11: =SUM(Q5:Q6) -> 500000 | J11: =IFERROR(B11/F11*100,"") -> 0 | N11: =MAX(C10-G10,0) -> #ERROR!
B13: PROGRESO ANUAL
B14: =REPT(CHAR(9608),MIN(INT(K10/10),10))&REPT(CHAR(9617),MAX(10-MIN(INT(K10/10),10),0))&" "&TEXT(K10,"0.0")&"% completado" -> #ERROR!

Sheet Mauro
B1: PERFIL DE FRANCO 2025
B3: Ingresos Anuales | D3: Gastos Anuales | F3: Balance Anual | H3: % Ahorro Anual
B4: =IFERROR('Enero'!C3+'Febrero'!C3+'Marzo'!C3+'Abril'!C3+'Mayo'!C3+'Junio'!C3+'Julio'!C3+'Agosto'!C3+'Septiembre'!C3+'Octubre'!C3+'Noviembre'!C3+'Diciembre'!C3,0) -> #ERROR! | D4: =IFERROR(SUMIFS('Enero'!F6:F55,'Enero'!C6:C55,"Franco")+SUMIFS('Febrero'!F6:F55,'Febrero'!C6:C55,"Franco")+SUMIFS('Marzo'!F6:F55,'Marzo'!C6:C55,"Franco")+SUMIFS('Abril'!F6:F55,'Abril'!C6:C55,"Franco")+SUMIFS('Mayo'!F6:F55,'Mayo'!C6:C55,"Franco")+SUMIFS('Junio'!F6:F55,'Junio'!C6:C55,"Franco")+SUMIFS('Julio'!F6:F55,'Julio'!C6:C55,"Franco")+SUMIFS('Agosto'!F6:F55,'Agosto'!C6:C55,"Franco")+SUMIFS('Septiembre'!F6:F55,'Septiembre'!C6:C55,"Franco")+SUMIFS('Octubre'!F6:F55,'Octubre'!C6:C55,"Franco")+SUMIFS('Noviembre'!F6:F55,'Noviembre'!C6:C55,"Franco")+SUMIFS('Diciembre'!F6:F55,'Diciembre'!C6:C55,"Franco"),0) -> #ERROR! | F4: =C4-E4 -> 0 | H4: =IFERROR(G4/C4*100,"")
B6: Mes | C6: Ingresos | D6: Gastos | E6: Balance | F6: % Ahorro | H6: GASTOS POR CATEGORIA
B7: Enero | C7: =IFERROR('Enero'!C3,0) -> #ERROR! | D7: =IFERROR(SUMIFS('Enero'!F6:F55,'Enero'!C6:C55,"Franco"),0) -> #ERROR! | E7: =C7-D7 -> #ERROR! | F7: =IFERROR(E7/C7*100,"") | H7: Categoria | I7: Total Anual
B8: Febrero | C8: =IFERROR('Febrero'!C3,0) -> #ERROR! | D8: =IFERROR(SUMIFS('Febrero'!F6:F55,'Febrero'!C6:C55,"Franco"),0) -> #ERROR! | E8: =C8-D8 -> #ERROR! | F8: =IFERROR(E8/C8*100,"") | H8: Alimentación | I8: =IFERROR(SUMIFS('Enero'!F6:F55,'Enero'!C6:C55,"Franco",'Enero'!E6:E55,"Alimentación")+SUMIFS('Febrero'!F6:F55,'Febrero'!C6:C55,"Franco",'Febrero'!E6:E55,"Alimentación")+SUMIFS('Marzo'!F6:F55,'Marzo'!C6:C55,"Franco",'Marzo'!E6:E55,"Alimentación")+SUMIFS('Abril'!F6:F55,'Abril'!C6:C55,"Franco",'Abril'!E6:E55,"Alimentación")+SUMIFS('Mayo'!F6:F55,'Mayo'!C6:C55,"Franco",'Mayo'!E6:E55,"Alimentación")+SUMIFS('Junio'!F6:F55,'Junio'!C6:C55,"Franco",'Junio'!E6:E55,"Alimentación")+SUMIFS('Julio'!F6:F55,'Julio'!C6:C55,"Franco",'Julio'!E6:E55,"Alimentación")+SUMIFS('Agosto'!F6:F55,'Agosto'!C6:C55,"Franco",'Agosto'!E6:E55,"Alimentación")+SUMIFS('Septiembre'!F6:F55,'Septiembre'!C6:C55,"Franco",'Septiembre'!E6:E55,"Alimentación")+SUMIFS('Octubre'!F6:F55,'Octubre'!C6:C55,"Franco",'Octubre'!E6:E55,"Alimentación")+SUMIFS('Noviembre'!F6:F55,'Noviembre'!C6:C55,"Franco",'Noviembre'!E6:E55,"Alimentación")+SUMIFS('Diciembre'!F6:F55,'Diciembre'!C6:C55,"Franco",'Diciembre'!E6:E55,"Alimentación"),0) -> #ERROR!
B9: Marzo | C9: =IFERROR('Marzo'!C3,0) -> #ERROR! | D9: =IFERROR(SUMIFS('Marzo'!F6:F55,'Marzo'!C6:C55,"Franco"),0) -> #ERROR! | E9: =C9-D9 -> #ERROR! | F9: =IFERROR(E9/C9*100,"") | H9: Transporte | I9: =IFERROR(SUMIFS('Enero'!F6:F55,'Enero'!C6:C55,"Franco",'Enero'!E6:E55,"Transporte")+SUMIFS('Febrero'!F6:F55,'Febrero'!C6:C55,"Franco",'Febrero'!E6:E55,"Transporte")+SUMIFS('Marzo'!F6:F55,'Marzo'!C6:C55,"Franco",'Marzo'!E6:E55,"Transporte")+SUMIFS('Abril'!F6:F55,'Abril'!C6:C55,"Franco",'Abril'!E6:E55,"Transporte")+SUMIFS('Mayo'!F6:F55,'Mayo'!C6:C55,"Franco",'Mayo'!E6:E55,"Transporte")+SUMIFS('Junio'!F6:F55,'Junio'!C6:C55,"Franco",'Junio'!E6:E55,"Transporte")+SUMIFS('Julio'!F6:F55,'Julio'!C6:C55,"Franco",'Julio'!E6:E55,"Transporte")+SUMIFS('Agosto'!F6:F55,'Agosto'!C6:C55,"Franco",'Agosto'!E6:E55,"Transporte")+SUMIFS('Septiembre'!F6:F55,'Septiembre'!C6:C55,"Franco",'Septiembre'!E6:E55,"Transporte")+SUMIFS('Octubre'!F6:F55,'Octubre'!C6:C55,"Franco",'Octubre'!E6:E55,"Transporte")+SUMIFS('Noviembre'!F6:F55,'Noviembre'!C6:C55,"Franco",'Noviembre'!E6:E55,"Transporte")+SUMIFS('Diciembre'!F6:F55,'Diciembre'!C6:C55,"Franco",'Diciembre'!E6:E55,"Transporte"),0) -> #ERROR!
B10: Abril | C10: =IFERROR('Abril'!C3,0) -> #ERROR! | D10: =IFERROR(SUMIFS('Abril'!F6:F55,'Abril'!C6:C55,"Franco"),0) -> #ERROR! | E10: =C10-D10 -> #ERROR! | F10: =IFERROR(E10/C10*100,"") | H10: Vivienda | I10: =IFERROR(SUMIFS('Enero'!F6:F55,'Enero'!C6:C55,"Franco",'Enero'!E6:E55,"Vivienda")+SUMIFS('Febrero'!F6:F55,'Febrero'!C6:C55,"Franco",'Febrero'!E6:E55,"Vivienda")+SUMIFS('Marzo'!F6:F55,'Marzo'!C6:C55,"Franco",'Marzo'!E6:E55,"Vivienda")+SUMIFS('Abril'!F6:F55,'Abril'!C6:C55,"Franco",'Abril'!E6:E55,"Vivienda")+SUMIFS('Mayo'!F6:F55,'Mayo'!C6:C55,"Franco",'Mayo'!E6:E55,"Vivienda")+SUMIFS('Junio'!F6:F55,'Junio'!C6:C55,"Franco",'Junio'!E6:E55,"Vivienda")+SUMIFS('Julio'!F6:F55,'Julio'!C6:C55,"Franco",'Julio'!E6:E55,"Vivienda")+SUMIFS('Agosto'!F6:F55,'Agosto'!C6:C55,"Franco",'Agosto'!E6:E55,"Vivienda")+SUMIFS('Septiembre'!F6:F55,'Septiembre'!C6:C55,"Franco",'Septiembre'!E6:E55,"Vivienda")+SUMIFS('Octubre'!F6:F55,'Octubre'!C6:C55,"Franco",'Octubre'!E6:E55,"Vivienda")+SUMIFS('Noviembre'!F6:F55,'Noviembre'!C6:C55,"Franco",'Noviembre'!E6:E55,"Vivienda")+SUMIFS('Diciembre'!F6:F55,'Diciembre'!C6:C55,"Franco",'Diciembre'!E6:E55,"Vivienda"),0) -> #ERROR!
B11: Mayo | C11: =IFERROR('Mayo'!C3,0) -> #ERROR! | D11: =IFERROR(SUMIFS('Mayo'!F6:F55,'Mayo'!C6:C55,"Franco"),0) -> #ERROR! | E11: =C11-D11 -> #ERROR! | F11: =IFERROR(E11/C11*100,"") | H11: Salud | I11: =IFERROR(SUMIFS('Enero'!F6:F55,'Enero'!C6:C55,"Franco",'Enero'!E6:E55,"Salud")+SUMIFS('Febrero'!F6:F55,'Febrero'!C6:C55,"Franco",'Febrero'!E6:E55,"Salud")+SUMIFS('Marzo'!F6:F55,'Marzo'!C6:C55,"Franco",'Marzo'!E6:E55,"Salud")+SUMIFS('Abril'!F6:F55,'Abril'!C6:C55,"Franco",'Abril'!E6:E55,"Salud")+SUMIFS('Mayo'!F6:F55,'Mayo'!C6:C55,"Franco",'Mayo'!E6:E55,"Salud")+SUMIFS('Junio'!F6:F55,'Junio'!C6:C55,"Franco",'Junio'!E6:E55,"Salud")+SUMIFS('Julio'!F6:F55,'Julio'!C6:C55,"Franco",'Julio'!E6:E55,"Salud")+SUMIFS('Agosto'!F6:F55,'Agosto'!C6:C55,"Franco",'Agosto'!E6:E55,"Salud")+SUMIFS('Septiembre'!F6:F55,'Septiembre'!C6:C55,"Franco",'Septiembre'!E6:E55,"Salud")+SUMIFS('Octubre'!F6:F55,'Octubre'!C6:C55,"Franco",'Octubre'!E6:E55,"Salud")+SUMIFS('Noviembre'!F6:F55,'Noviembre'!C6:C55,"Franco",'Noviembre'!E6:E55,"Salud")+SUMIFS('Diciembre'!F6:F55,'Diciembre'!C6:C55,"Franco",'Diciembre'!E6:E55,"Salud"),0) -> #ERROR!
B12: Junio | C12: =IFERROR('Junio'!C3,0) -> #ERROR! | D12: =IFERROR(SUMIFS('Junio'!F6:F55,'Junio'!C6:C55,"Franco"),0) -> #ERROR! | E12: =C12-D12 -> #ERROR! | F12: =IFERROR(E12/C12*100,"") | H12: Educación | I12: =IFERROR(SUMIFS('Enero'!F6:F55,'Enero'!C6:C55,"Franco",'Enero'!E6:E55,"Educación")+SUMIFS('Febrero'!F6:F55,'Febrero'!C6:C55,"Franco",'Febrero'!E6:E55,"Educación")+SUMIFS('Marzo'!F6:F55,'Marzo'!C6:C55,"Franco",'Marzo'!E6:E55,"Educación")+SUMIFS('Abril'!F6:F55,'Abril'!C6:C55,"Franco",'Abril'!E6:E55,"Educación")+SUMIFS('Mayo'!F6:F55,'Mayo'!C6:C55,"Franco",'Mayo'!E6:E55,"Educación")+SUMIFS('Junio'!F6:F55,'Junio'!C6:C55,"Franco",'Junio'!E6:E55,"Educación")+SUMIFS('Julio'!F6:F55,'Julio'!C6:C55,"Franco",'Julio'!E6:E55,"Educación")+SUMIFS('Agosto'!F6:F55,'Agosto'!C6:C55,"Franco",'Agosto'!E6:E55,"Educación")+SUMIFS('Septiembre'!F6:F55,'Septiembre'!C6:C55,"Franco",'Septiembre'!E6:E55,"Educación")+SUMIFS('Octubre'!F6:F55,'Octubre'!C6:C55,"Franco",'Octubre'!E6:E55,"Educación")+SUMIFS('Noviembre'!F6:F55,'Noviembre'!C6:C55,"Franco",'Noviembre'!E6:E55,"Educación")+SUMIFS('Diciembre'!F6:F55,'Diciembre'!C6:C55,"Franco",'Diciembre'!E6:E55,"Educación"),0) -> #ERROR!
B13: Julio | C13: =IFERROR('Julio'!C3,0) -> #ERROR! | D13: =IFERROR(SUMIFS('Julio'!F6:F55,'Julio'!C6:C55,"Franco"),0) -> #ERROR! | E13: =C13-D13 -> #ERROR! | F13: =IFERROR(E13/C13*100,"") | H13: Entretenimiento | I13: =IFERROR(SUMIFS('Enero'!F6:F55,'Enero'!C6:C55,"Franco",'Enero'!E6:E55,"Entretenimiento")+SUMIFS('Febrero'!F6:F55,'Febrero'!C6:C55,"Franco",'Febrero'!E6:E55,"Entretenimiento")+SUMIFS('Marzo'!F6:F55,'Marzo'!C6:C55,"Franco",'Marzo'!E6:E55,"Entretenimiento")+SUMIFS('Abril'!F6:F55,'Abril'!C6:C55,"Franco",'Abril'!E6:E55,"Entretenimiento")+SUMIFS('Mayo'!F6:F55,'Mayo'!C6:C55,"Franco",'Mayo'!E6:E55,"Entretenimiento")+SUMIFS('Junio'!F6:F55,'Junio'!C6:C55,"Franco",'Junio'!E6:E55,"Entretenimiento")+SUMIFS('Julio'!F6:F55,'Julio'!C6:C55,"Franco",'Julio'!E6:E55,"Entretenimiento")+SUMIFS('Agosto'!F6:F55,'Agosto'!C6:C55,"Franco",'Agosto'!E6:E55,"Entretenimiento")+SUMIFS('Septiembre'!F6:F55,'Septiembre'!C6:C55,"Franco",'Septiembre'!E6:E55,"Entretenimiento")+SUMIFS('Octubre'!F6:F55,'Octubre'!C6:C55,"Franco",'Octubre'!E6:E55,"Entretenimiento")+SUMIFS('Noviembre'!F6:F55,'Noviembre'!C6:C55,"Franco",'Noviembre'!E6:E55,"Entretenimiento")+SUMIFS('Diciembre'!F6:F55,'Diciembre'!C6:C55,"Franco",'Diciembre'!E6:E55,"Entretenimiento"),0) -> #ERROR!
B14: Agosto | C14: =IFERROR('Agosto'!C3,0) -> #ERROR! | D14: =IFERROR(SUMIFS('Agosto'!F6:F55,'Agosto'!C6:C55,"Franco"),0) -> #ERROR! | E14: =C14-D14 -> #ERROR! | F14: =IFERROR(E14/C14*100,"") | H14: Ropa | I14: =IFERROR(SUMIFS('Enero'!F6:F55,'Enero'!C6:C55,"Franco",'Enero'!E6:E55,"Ropa")+SUMIFS('Febrero'!F6:F55,'Febrero'!C6:C55,"Franco",'Febrero'!E6:E55,"Ropa")+SUMIFS('Marzo'!F6:F55,'Marzo'!C6:C55,"Franco",'Marzo'!E6:E55,"Ropa")+SUMIFS('Abril'!F6:F55,'Abril'!C6:C55,"Franco",'Abril'!E6:E55,"Ropa")+SUMIFS('Mayo'!F6:F55,'Mayo'!C6:C55,"Franco",'Mayo'!E6:E55,"Ropa")+SUMIFS('Junio'!F6:F55,'Junio'!C6:C55,"Franco",'Junio'!E6:E55,"Ropa")+SUMIFS('Julio'!F6:F55,'Julio'!C6:C55,"Franco",'Julio'!E6:E55,"Ropa")+SUMIFS('Agosto'!F6:F55,'Agosto'!C6:C55,"Franco",'Agosto'!E6:E55,"Ropa")+SUMIFS('Septiembre'!F6:F55,'Septiembre'!C6:C55,"Franco",'Septiembre'!E6:E55,"Ropa")+SUMIFS('Octubre'!F6:F55,'Octubre'!C6:C55,"Franco",'Octubre'!E6:E55,"Ropa")+SUMIFS('Noviembre'!F6:F55,'Noviembre'!C6:C55,"Franco",'Noviembre'!E6:E55,"Ropa")+SUMIFS('Diciembre'!F6:F55,'Diciembre'!C6:C55,"Franco",'Diciembre'!E6:E55,"Ropa"),0) -> #ERROR!
B15: Septiembre | C15: =IFERROR('Septiembre'!C3,0) -> #ERROR! | D15: =IFERROR(SUMIFS('Septiembre'!F6:F55,'Septiembre'!C6:C55,"Franco"),0) -> #ERROR! | E15: =C15-D15 -> #ERROR! | F15: =IFERROR(E15/C15*100,"") | H15: Servicios | I15: =IFERROR(SUMIFS('Enero'!F6:F55,'Enero'!C6:C55,"Franco",'Enero'!E6:E55,"Servicios")+SUMIFS('Febrero'!F6:F55,'Febrero'!C6:C55,"Franco",'Febrero'!E6:E55,"Servicios")+SUMIFS('Marzo'!F6:F55,'Marzo'!C6:C55,"Franco",'Marzo'!E6:E55,"Servicios")+SUMIFS('Abril'!F6:F55,'Abril'!C6:C55,"Franco",'Abril'!E6:E55,"Servicios")+SUMIFS('Mayo'!F6:F55,'Mayo'!C6:C55,"Franco",'Mayo'!E6:E55,"Servicios")+SUMIFS('Junio'!F6:F55,'Junio'!C6:C55,"Franco",'Junio'!E6:E55,"Servicios")+SUMIFS('Julio'!F6:F55,'Julio'!C6:C55,"Franco",'Julio'!E6:E55,"Servicios")+SUMIFS('Agosto'!F6:F55,'Agosto'!C6:C55,"Franco",'Agosto'!E6:E55,"Servicios")+SUMIFS('Septiembre'!F6:F55,'Septiembre'!C6:C55,"Franco",'Septiembre'!E6:E55,"Servicios")+SUMIFS('Octubre'!F6:F55,'Octubre'!C6:C55,"Franco",'Octubre'!E6:E55,"Servicios")+SUMIFS('Noviembre'!F6:F55,'Noviembre'!C6:C55,"Franco",'Noviembre'!E6:E55,"Servicios")+SUMIFS('Diciembre'!F6:F55,'Diciembre'!C6:C55,"Franco",'Diciembre'!E6:E55,"Servicios"),0) -> #ERROR!
B16: Octubre | C16: =IFERROR('Octubre'!C3,0) -> #ERROR! | D16: =IFERROR(SUMIFS('Octubre'!F6:F55,'Octubre'!C6:C55,"Franco"),0) -> #ERROR! | E16: =C16-D16 -> #ERROR! | F16: =IFERROR(E16/C16*100,"") | H16: Ahorro | I16: =IFERROR(SUMIFS('Enero'!F6:F55,'Enero'!C6:C55,"Franco",'Enero'!E6:E55,"Ahorro")+SUMIFS('Febrero'!F6:F55,'Febrero'!C6:C55,"Franco",'Febrero'!E6:E55,"Ahorro")+SUMIFS('Marzo'!F6:F55,'Marzo'!C6:C55,"Franco",'Marzo'!E6:E55,"Ahorro")+SUMIFS('Abril'!F6:F55,'Abril'!C6:C55,"Franco",'Abril'!E6:E55,"Ahorro")+SUMIFS('Mayo'!F6:F55,'Mayo'!C6:C55,"Franco",'Mayo'!E6:E55,"Ahorro")+SUMIFS('Junio'!F6:F55,'Junio'!C6:C55,"Franco",'Junio'!E6:E55,"Ahorro")+SUMIFS('Julio'!F6:F55,'Julio'!C6:C55,"Franco",'Julio'!E6:E55,"Ahorro")+SUMIFS('Agosto'!F6:F55,'Agosto'!C6:C55,"Franco",'Agosto'!E6:E55,"Ahorro")+SUMIFS('Septiembre'!F6:F55,'Septiembre'!C6:C55,"Franco",'Septiembre'!E6:E55,"Ahorro")+SUMIFS('Octubre'!F6:F55,'Octubre'!C6:C55,"Franco",'Octubre'!E6:E55,"Ahorro")+SUMIFS('Noviembre'!F6:F55,'Noviembre'!C6:C55,"Franco",'Noviembre'!E6:E55,"Ahorro")+SUMIFS('Diciembre'!F6:F55,'Diciembre'!C6:C55,"Franco",'Diciembre'!E6:E55,"Ahorro"),0) -> #ERROR!
B17: Noviembre | C17: =IFERROR('Noviembre'!C3,0) -> #ERROR! | D17: =IFERROR(SUMIFS('Noviembre'!F6:F55,'Noviembre'!C6:C55,"Franco"),0) -> #ERROR! | E17: =C17-D17 -> #ERROR! | F17: =IFERROR(E17/C17*100,"") | H17: Otros | I17: =IFERROR(SUMIFS('Enero'!F6:F55,'Enero'!C6:C55,"Franco",'Enero'!E6:E55,"Otros")+SUMIFS('Febrero'!F6:F55,'Febrero'!C6:C55,"Franco",'Febrero'!E6:E55,"Otros")+SUMIFS('Marzo'!F6:F55,'Marzo'!C6:C55,"Franco",'Marzo'!E6:E55,"Otros")+SUMIFS('Abril'!F6:F55,'Abril'!C6:C55,"Franco",'Abril'!E6:E55,"Otros")+SUMIFS('Mayo'!F6:F55,'Mayo'!C6:C55,"Franco",'Mayo'!E6:E55,"Otros")+SUMIFS('Junio'!F6:F55,'Junio'!C6:C55,"Franco",'Junio'!E6:E55,"Otros")+SUMIFS('Julio'!F6:F55,'Julio'!C6:C55,"Franco",'Julio'!E6:E55,"Otros")+SUMIFS('Agosto'!F6:F55,'Agosto'!C6:C55,"Franco",'Agosto'!E6:E55,"Otros")+SUMIFS('Septiembre'!F6:F55,'Septiembre'!C6:C55,"Franco",'Septiembre'!E6:E55,"Otros")+SUMIFS('Octubre'!F6:F55,'Octubre'!C6:C55,"Franco",'Octubre'!E6:E55,"Otros")+SUMIFS('Noviembre'!F6:F55,'Noviembre'!C6:C55,"Franco",'Noviembre'!E6:E55,"Otros")+SUMIFS('Diciembre'!F6:F55,'Diciembre'!C6:C55,"Franco",'Diciembre'!E6:E55,"Otros"),0) -> #ERROR!
B18: Diciembre | C18: =IFERROR('Diciembre'!C3,0) -> #ERROR! | D18: =IFERROR(SUMIFS('Diciembre'!F6:F55,'Diciembre'!C6:C55,"Franco"),0) -> #ERROR! | E18: =C18-D18 -> #ERROR! | F18: =IFERROR(E18/C18*100,"")
B19: TOTAL | C19: =SUM(C7:C18) -> #ERROR! | D19: =SUM(D7:D18) -> #ERROR! | E19: =C19-D19 -> #ERROR! | F19: =IFERROR(E19/C19*100,"")

Sheet Daiana
B1: PERFIL DE PAREJA 2025
B3: Ingresos Anuales | D3: Gastos Anuales | F3: Balance Anual | H3: % Ahorro Anual
B4: =IFERROR('Enero'!D3+'Febrero'!D3+'Marzo'!D3+'Abril'!D3+'Mayo'!D3+'Junio'!D3+'Julio'!D3+'Agosto'!D3+'Septiembre'!D3+'Octubre'!D3+'Noviembre'!D3+'Diciembre'!D3,0) -> #ERROR! | D4: =IFERROR(SUMIFS('Enero'!F6:F55,'Enero'!C6:C55,"Pareja")+SUMIFS('Febrero'!F6:F55,'Febrero'!C6:C55,"Pareja")+SUMIFS('Marzo'!F6:F55,'Marzo'!C6:C55,"Pareja")+SUMIFS('Abril'!F6:F55,'Abril'!C6:C55,"Pareja")+SUMIFS('Mayo'!F6:F55,'Mayo'!C6:C55,"Pareja")+SUMIFS('Junio'!F6:F55,'Junio'!C6:C55,"Pareja")+SUMIFS('Julio'!F6:F55,'Julio'!C6:C55,"Pareja")+SUMIFS('Agosto'!F6:F55,'Agosto'!C6:C55,"Pareja")+SUMIFS('Septiembre'!F6:F55,'Septiembre'!C6:C55,"Pareja")+SUMIFS('Octubre'!F6:F55,'Octubre'!C6:C55,"Pareja")+SUMIFS('Noviembre'!F6:F55,'Noviembre'!C6:C55,"Pareja")+SUMIFS('Diciembre'!F6:F55,'Diciembre'!C6:C55,"Pareja"),0) -> #ERROR! | F4: =C4-E4 -> 0 | H4: =IFERROR(G4/C4*100,"")
B6: Mes | C6: Ingresos | D6: Gastos | E6: Balance | F6: % Ahorro | H6: GASTOS POR CATEGORIA
B7: Enero | C7: =IFERROR('Enero'!D3,0) -> #ERROR! | D7: =IFERROR(SUMIFS('Enero'!F6:F55,'Enero'!C6:C55,"Pareja"),0) -> #ERROR! | E7: =C7-D7 -> #ERROR! | F7: =IFERROR(E7/C7*100,"") | H7: Categoria | I7: Total Anual
B8: Febrero | C8: =IFERROR('Febrero'!D3,0) -> #ERROR! | D8: =IFERROR(SUMIFS('Febrero'!F6:F55,'Febrero'!C6:C55,"Pareja"),0) -> #ERROR! | E8: =C8-D8 -> #ERROR! | F8: =IFERROR(E8/C8*100,"") | H8: Alimentación | I8: =IFERROR(SUMIFS('Enero'!F6:F55,'Enero'!C6:C55,"Pareja",'Enero'!E6:E55,"Alimentación")+SUMIFS('Febrero'!F6:F55,'Febrero'!C6:C55,"Pareja",'Febrero'!E6:E55,"Alimentación")+SUMIFS('Marzo'!F6:F55,'Marzo'!C6:C55,"Pareja",'Marzo'!E6:E55,"Alimentación")+SUMIFS('Abril'!F6:F55,'Abril'!C6:C55,"Pareja",'Abril'!E6:E55,"Alimentación")+SUMIFS('Mayo'!F6:F55,'Mayo'!C6:C55,"Pareja",'Mayo'!E6:E55,"Alimentación")+SUMIFS('Junio'!F6:F55,'Junio'!C6:C55,"Pareja",'Junio'!E6:E55,"Alimentación")+SUMIFS('Julio'!F6:F55,'Julio'!C6:C55,"Pareja",'Julio'!E6:E55,"Alimentación")+SUMIFS('Agosto'!F6:F55,'Agosto'!C6:C55,"Pareja",'Agosto'!E6:E55,"Alimentación")+SUMIFS('Septiembre'!F6:F55,'Septiembre'!C6:C55,"Pareja",'Septiembre'!E6:E55,"Alimentación")+SUMIFS('Octubre'!F6:F55,'Octubre'!C6:C55,"Pareja",'Octubre'!E6:E55,"Alimentación")+SUMIFS('Noviembre'!F6:F55,'Noviembre'!C6:C55,"Pareja",'Noviembre'!E6:E55,"Alimentación")+SUMIFS('Diciembre'!F6:F55,'Diciembre'!C6:C55,"Pareja",'Diciembre'!E6:E55,"Alimentación"),0) -> #ERROR!
B9: Marzo | C9: =IFERROR('Marzo'!D3,0) -> #ERROR! | D9: =IFERROR(SUMIFS('Marzo'!F6:F55,'Marzo'!C6:C55,"Pareja"),0) -> #ERROR! | E9: =C9-D9 -> #ERROR! | F9: =IFERROR(E9/C9*100,"") | H9: Transporte | I9: =IFERROR(SUMIFS('Enero'!F6:F55,'Enero'!C6:C55,"Pareja",'Enero'!E6:E55,"Transporte")+SUMIFS('Febrero'!F6:F55,'Febrero'!C6:C55,"Pareja",'Febrero'!E6:E55,"Transporte")+SUMIFS('Marzo'!F6:F55,'Marzo'!C6:C55,"Pareja",'Marzo'!E6:E55,"Transporte")+SUMIFS('Abril'!F6:F55,'Abril'!C6:C55,"Pareja",'Abril'!E6:E55,"Transporte")+SUMIFS('Mayo'!F6:F55,'Mayo'!C6:C55,"Pareja",'Mayo'!E6:E55,"Transporte")+SUMIFS('Junio'!F6:F55,'Junio'!C6:C55,"Pareja",'Junio'!E6:E55,"Transporte")+SUMIFS('Julio'!F6:F55,'Julio'!C6:C55,"Pareja",'Julio'!E6:E55,"Transporte")+SUMIFS('Agosto'!F6:F55,'Agosto'!C6:C55,"Pareja",'Agosto'!E6:E55,"Transporte")+SUMIFS('Septiembre'!F6:F55,'Septiembre'!C6:C55,"Pareja",'Septiembre'!E6:E55,"Transporte")+SUMIFS('Octubre'!F6:F55,'Octubre'!C6:C55,"Pareja",'Octubre'!E6:E55,"Transporte")+SUMIFS('Noviembre'!F6:F55,'Noviembre'!C6:C55,"Pareja",'Noviembre'!E6:E55,"Transporte")+SUMIFS('Diciembre'!F6:F55,'Diciembre'!C6:C55,"Pareja",'Diciembre'!E6:E55,"Transporte"),0) -> #ERROR!
B10: Abril | C10: =IFERROR('Abril'!D3,0) -> #ERROR! | D10: =IFERROR(SUMIFS('Abril'!F6:F55,'Abril'!C6:C55,"Pareja"),0) -> #ERROR! | E10: =C10-D10 -> #ERROR! | F10: =IFERROR(E10/C10*100,"") | H10: Vivienda | I10: =IFERROR(SUMIFS('Enero'!F6:F55,'Enero'!C6:C55,"Pareja",'Enero'!E6:E55,"Vivienda")+SUMIFS('Febrero'!F6:F55,'Febrero'!C6:C55,"Pareja",'Febrero'!E6:E55,"Vivienda")+SUMIFS('Marzo'!F6:F55,'Marzo'!C6:C55,"Pareja",'Marzo'!E6:E55,"Vivienda")+SUMIFS('Abril'!F6:F55,'Abril'!C6:C55,"Pareja",'Abril'!E6:E55,"Vivienda")+SUMIFS('Mayo'!F6:F55,'Mayo'!C6:C55,"Pareja",'Mayo'!E6:E55,"Vivienda")+SUMIFS('Junio'!F6:F55,'Junio'!C6:C55,"Pareja",'Junio'!E6:E55,"Vivienda")+SUMIFS('Julio'!F6:F55,'Julio'!C6:C55,"Pareja",'Julio'!E6:E55,"Vivienda")+SUMIFS('Agosto'!F6:F55,'Agosto'!C6:C55,"Pareja",'Agosto'!E6:E55,"Vivienda")+SUMIFS('Septiembre'!F6:F55,'Septiembre'!C6:C55,"Pareja",'Septiembre'!E6:E55,"Vivienda")+SUMIFS('Octubre'!F6:F55,'Octubre'!C6:C55,"Pareja",'Octubre'!E6:E55,"Vivienda")+SUMIFS('Noviembre'!F6:F55,'Noviembre'!C6:C55,"Pareja",'Noviembre'!E6:E55,"Vivienda")+SUMIFS('Diciembre'!F6:F55,'Diciembre'!C6:C55,"Pareja",'Diciembre'!E6:E55,"Vivienda"),0) -> #ERROR!
B11: Mayo | C11: =IFERROR('Mayo'!D3,0) -> #ERROR! | D11: =IFERROR(SUMIFS('Mayo'!F6:F55,'Mayo'!C6:C55,"Pareja"),0) -> #ERROR! | E11: =C11-D11 -> #ERROR! | F11: =IFERROR(E11/C11*100,"") | H11: Salud | I11: =IFERROR(SUMIFS('Enero'!F6:F55,'Enero'!C6:C55,"Pareja",'Enero'!E6:E55,"Salud")+SUMIFS('Febrero'!F6:F55,'Febrero'!C6:C55,"Pareja",'Febrero'!E6:E55,"Salud")+SUMIFS('Marzo'!F6:F55,'Marzo'!C6:C55,"Pareja",'Marzo'!E6:E55,"Salud")+SUMIFS('Abril'!F6:F55,'Abril'!C6:C55,"Pareja",'Abril'!E6:E55,"Salud")+SUMIFS('Mayo'!F6:F55,'Mayo'!C6:C55,"Pareja",'Mayo'!E6:E55,"Salud")+SUMIFS('Junio'!F6:F55,'Junio'!C6:C55,"Pareja",'Junio'!E6:E55,"Salud")+SUMIFS('Julio'!F6:F55,'Julio'!C6:C55,"Pareja",'Julio'!E6:E55,"Salud")+SUMIFS('Agosto'!F6:F55,'Agosto'!C6:C55,"Pareja",'Agosto'!E6:E55,"Salud")+SUMIFS('Septiembre'!F6:F55,'Septiembre'!C6:C55,"Pareja",'Septiembre'!E6:E55,"Salud")+SUMIFS('Octubre'!F6:F55,'Octubre'!C6:C55,"Pareja",'Octubre'!E6:E55,"Salud")+SUMIFS('Noviembre'!F6:F55,'Noviembre'!C6:C55,"Pareja",'Noviembre'!E6:E55,"Salud")+SUMIFS('Diciembre'!F6:F55,'Diciembre'!C6:C55,"Pareja",'Diciembre'!E6:E55,"Salud"),0) -> #ERROR!
B12: Junio | C12: =IFERROR('Junio'!D3,0) -> #ERROR! | D12: =IFERROR(SUMIFS('Junio'!F6:F55,'Junio'!C6:C55,"Pareja"),0) -> #ERROR! | E12: =C12-D12 -> #ERROR! | F12: =IFERROR(E12/C12*100,"") | H12: Educación | I12: =IFERROR(SUMIFS('Enero'!F6:F55,'Enero'!C6:C55,"Pareja",'Enero'!E6:E55,"Educación")+SUMIFS('Febrero'!F6:F55,'Febrero'!C6:C55,"Pareja",'Febrero'!E6:E55,"Educación")+SUMIFS('Marzo'!F6:F55,'Marzo'!C6:C55,"Pareja",'Marzo'!E6:E55,"Educación")+SUMIFS('Abril'!F6:F55,'Abril'!C6:C55,"Pareja",'Abril'!E6:E55,"Educación")+SUMIFS('Mayo'!F6:F55,'Mayo'!C6:C55,"Pareja",'Mayo'!E6:E55,"Educación")+SUMIFS('Junio'!F6:F55,'Junio'!C6:C55,"Pareja",'Junio'!E6:E55,"Educación")+SUMIFS('Julio'!F6:F55,'Julio'!C6:C55,"Pareja",'Julio'!E6:E55,"Educación")+SUMIFS('Agosto'!F6:F55,'Agosto'!C6:C55,"Pareja",'Agosto'!E6:E55,"Educación")+SUMIFS('Septiembre'!F6:F55,'Septiembre'!C6:C55,"Pareja",'Septiembre'!E6:E55,"Educación")+SUMIFS('Octubre'!F6:F55,'Octubre'!C6:C55,"Pareja",'Octubre'!E6:E55,"Educación")+SUMIFS('Noviembre'!F6:F55,'Noviembre'!C6:C55,"Pareja",'Noviembre'!E6:E55,"Educación")+SUMIFS('Diciembre'!F6:F55,'Diciembre'!C6:C55,"Pareja",'Diciembre'!E6:E55,"Educación"),0) -> #ERROR!
B13: Julio | C13: =IFERROR('Julio'!D3,0) -> #ERROR! | D13: =IFERROR(SUMIFS('Julio'!F6:F55,'Julio'!C6:C55,"Pareja"),0) -> #ERROR! | E13: =C13-D13 -> #ERROR! | F13: =IFERROR(E13/C13*100,"") | H13: Entretenimiento | I13: =IFERROR(SUMIFS('Enero'!F6:F55,'Enero'!C6:C55,"Pareja",'Enero'!E6:E55,"Entretenimiento")+SUMIFS('Febrero'!F6:F55,'Febrero'!C6:C55,"Pareja",'Febrero'!E6:E55,"Entretenimiento")+SUMIFS('Marzo'!F6:F55,'Marzo'!C6:C55,"Pareja",'Marzo'!E6:E55,"Entretenimiento")+SUMIFS('Abril'!F6:F55,'Abril'!C6:C55,"Pareja",'Abril'!E6:E55,"Entretenimiento")+SUMIFS('Mayo'!F6:F55,'Mayo'!C6:C55,"Pareja",'Mayo'!E6:E55,"Entretenimiento")+SUMIFS('Junio'!F6:F55,'Junio'!C6:C55,"Pareja",'Junio'!E6:E55,"Entretenimiento")+SUMIFS('Julio'!F6:F55,'Julio'!C6:C55,"Pareja",'Julio'!E6:E55,"Entretenimiento")+SUMIFS('Agosto'!F6:F55,'Agosto'!C6:C55,"Pareja",'Agosto'!E6:E55,"Entretenimiento")+SUMIFS('Septiembre'!F6:F55,'Septiembre'!C6:C55,"Pareja",'Septiembre'!E6:E55,"Entretenimiento")+SUMIFS('Octubre'!F6:F55,'Octubre'!C6:C55,"Pareja",'Octubre'!E6:E55,"Entretenimiento")+SUMIFS('Noviembre'!F6:F55,'Noviembre'!C6:C55,"Pareja",'Noviembre'!E6:E55,"Entretenimiento")+SUMIFS('Diciembre'!F6:F55,'Diciembre'!C6:C55,"Pareja",'Diciembre'!E6:E55,"Entretenimiento"),0) -> #ERROR!
B14: Agosto | C14: =IFERROR('Agosto'!D3,0) -> #ERROR! | D14: =IFERROR(SUMIFS('Agosto'!F6:F55,'Agosto'!C6:C55,"Pareja"),0) -> #ERROR! | E14: =C14-D14 -> #ERROR! | F14: =IFERROR(E14/C14*100,"") | H14: Ropa | I14: =IFERROR(SUMIFS('Enero'!F6:F55,'Enero'!C6:C55,"Pareja",'Enero'!E6:E55,"Ropa")+SUMIFS('Febrero'!F6:F55,'Febrero'!C6:C55,"Pareja",'Febrero'!E6:E55,"Ropa")+SUMIFS('Marzo'!F6:F55,'Marzo'!C6:C55,"Pareja",'Marzo'!E6:E55,"Ropa")+SUMIFS('Abril'!F6:F55,'Abril'!C6:C55,"Pareja",'Abril'!E6:E55,"Ropa")+SUMIFS('Mayo'!F6:F55,'Mayo'!C6:C55,"Pareja",'Mayo'!E6:E55,"Ropa")+SUMIFS('Junio'!F6:F55,'Junio'!C6:C55,"Pareja",'Junio'!E6:E55,"Ropa")+SUMIFS('Julio'!F6:F55,'Julio'!C6:C55,"Pareja",'Julio'!E6:E55,"Ropa")+SUMIFS('Agosto'!F6:F55,'Agosto'!C6:C55,"Pareja",'Agosto'!E6:E55,"Ropa")+SUMIFS('Septiembre'!F6:F55,'Septiembre'!C6:C55,"Pareja",'Septiembre'!E6:E55,"Ropa")+SUMIFS('Octubre'!F6:F55,'Octubre'!C6:C55,"Pareja",'Octubre'!E6:E55,"Ropa")+SUMIFS('Noviembre'!F6:F55,'Noviembre'!C6:C55,"Pareja",'Noviembre'!E6:E55,"Ropa")+SUMIFS('Diciembre'!F6:F55,'Diciembre'!C6:C55,"Pareja",'Diciembre'!E6:E55,"Ropa"),0) -> #ERROR!
B15: Septiembre | C15: =IFERROR('Septiembre'!D3,0) -> #ERROR! | D15: =IFERROR(SUMIFS('Septiembre'!F6:F55,'Septiembre'!C6:C55,"Pareja"),0) -> #ERROR! | E15: =C15-D15 -> #ERROR! | F15: =IFERROR(E15/C15*100,"") | H15: Servicios | I15: =IFERROR(SUMIFS('Enero'!F6:F55,'Enero'!C6:C55,"Pareja",'Enero'!E6:E55,"Servicios")+SUMIFS('Febrero'!F6:F55,'Febrero'!C6:C55,"Pareja",'Febrero'!E6:E55,"Servicios")+SUMIFS('Marzo'!F6:F55,'Marzo'!C6:C55,"Pareja",'Marzo'!E6:E55,"Servicios")+SUMIFS('Abril'!F6:F55,'Abril'!C6:C55,"Pareja",'Abril'!E6:E55,"Servicios")+SUMIFS('Mayo'!F6:F55,'Mayo'!C6:C55,"Pareja",'Mayo'!E6:E55,"Servicios")+SUMIFS('Junio'!F6:F55,'Junio'!C6:C55,"Pareja",'Junio'!E6:E55,"Servicios")+SUMIFS('Julio'!F6:F55,'Julio'!C6:C55,"Pareja",'Julio'!E6:E55,"Servicios")+SUMIFS('Agosto'!F6:F55,'Agosto'!C6:C55,"Pareja",'Agosto'!E6:E55,"Servicios")+SUMIFS('Septiembre'!F6:F55,'Septiembre'!C6:C55,"Pareja",'Septiembre'!E6:E55,"Servicios")+SUMIFS('Octubre'!F6:F55,'Octubre'!C6:C55,"Pareja",'Octubre'!E6:E55,"Servicios")+SUMIFS('Noviembre'!F6:F55,'Noviembre'!C6:C55,"Pareja",'Noviembre'!E6:E55,"Servicios")+SUMIFS('Diciembre'!F6:F55,'Diciembre'!C6:C55,"Pareja",'Diciembre'!E6:E55,"Servicios"),0) -> #ERROR!
B16: Octubre | C16: =IFERROR('Octubre'!D3,0) -> #ERROR! | D16: =IFERROR(SUMIFS('Octubre'!F6:F55,'Octubre'!C6:C55,"Pareja"),0) -> #ERROR! | E16: =C16-D16 -> #ERROR! | F16: =IFERROR(E16/C16*100,"") | H16: Ahorro | I16: =IFERROR(SUMIFS('Enero'!F6:F55,'Enero'!C6:C55,"Pareja",'Enero'!E6:E55,"Ahorro")+SUMIFS('Febrero'!F6:F55,'Febrero'!C6:C55,"Pareja",'Febrero'!E6:E55,"Ahorro")+SUMIFS('Marzo'!F6:F55,'Marzo'!C6:C55,"Pareja",'Marzo'!E6:E55,"Ahorro")+SUMIFS('Abril'!F6:F55,'Abril'!C6:C55,"Pareja",'Abril'!E6:E55,"Ahorro")+SUMIFS('Mayo'!F6:F55,'Mayo'!C6:C55,"Pareja",'Mayo'!E6:E55,"Ahorro")+SUMIFS('Junio'!F6:F55,'Junio'!C6:C55,"Pareja",'Junio'!E6:E55,"Ahorro")+SUMIFS('Julio'!F6:F55,'Julio'!C6:C55,"Pareja",'Julio'!E6:E55,"Ahorro")+SUMIFS('Agosto'!F6:F55,'Agosto'!C6:C55,"Pareja",'Agosto'!E6:E55,"Ahorro")+SUMIFS('Septiembre'!F6:F55,'Septiembre'!C6:C55,"Pareja",'Septiembre'!E6:E55,"Ahorro")+SUMIFS('Octubre'!F6:F55,'Octubre'!C6:C55,"Pareja",'Octubre'!E6:E55,"Ahorro")+SUMIFS('Noviembre'!F6:F55,'Noviembre'!C6:C55,"Pareja",'Noviembre'!E6:E55,"Ahorro")+SUMIFS('Diciembre'!F6:F55,'Diciembre'!C6:C55,"Pareja",'Diciembre'!E6:E55,"Ahorro"),0) -> #ERROR!
B17: Noviembre | C17: =IFERROR('Noviembre'!D3,0) -> #ERROR! | D17: =IFERROR(SUMIFS('Noviembre'!F6:F55,'Noviembre'!C6:C55,"Pareja"),0) -> #ERROR! | E17: =C17-D17 -> #ERROR! | F17: =IFERROR(E17/C17*100,"") | H17: Otros | I17: =IFERROR(SUMIFS('Enero'!F6:F55,'Enero'!C6:C55,"Pareja",'Enero'!E6:E55,"Otros")+SUMIFS('Febrero'!F6:F55,'Febrero'!C6:C55,"Pareja",'Febrero'!E6:E55,"Otros")+SUMIFS('Marzo'!F6:F55,'Marzo'!C6:C55,"Pareja",'Marzo'!E6:E55,"Otros")+SUMIFS('Abril'!F6:F55,'Abril'!C6:C55,"Pareja",'Abril'!E6:E55,"Otros")+SUMIFS('Mayo'!F6:F55,'Mayo'!C6:C55,"Pareja",'Mayo'!E6:E55,"Otros")+SUMIFS('Junio'!F6:F55,'Junio'!C6:C55,"Pareja",'Junio'!E6:E55,"Otros")+SUMIFS('Julio'!F6:F55,'Julio'!C6:C55,"Pareja",'Julio'!E6:E55,"Otros")+SUMIFS('Agosto'!F6:F55,'Agosto'!C6:C55,"Pareja",'Agosto'!E6:E55,"Otros")+SUMIFS('Septiembre'!F6:F55,'Septiembre'!C6:C55,"Pareja",'Septiembre'!E6:E55,"Otros")+SUMIFS('Octubre'!F6:F55,'Octubre'!C6:C55,"Pareja",'Octubre'!E6:E55,"Otros")+SUMIFS('Noviembre'!F6:F55,'Noviembre'!C6:C55,"Pareja",'Noviembre'!E6:E55,"Otros")+SUMIFS('Diciembre'!F6:F55,'Diciembre'!C6:C55,"Pareja",'Diciembre'!E6:E55,"Otros"),0) -> #ERROR!
B18: Diciembre | C18: =IFERROR('Diciembre'!D3,0) -> #ERROR! | D18: =IFERROR(SUMIFS('Diciembre'!F6:F55,'Diciembre'!C6:C55,"Pareja"),0) -> #ERROR! | E18: =C18-D18 -> #ERROR! | F18: =IFERROR(E18/C18*100,"")
B19: TOTAL | C19: =SUM(C7:C18) -> #ERROR! | D19: =SUM(D7:D18) -> #ERROR! | E19: =C19-D19 -> #ERROR! | F19: =IFERROR(E19/C19*100,"")

Sheet Enero
B1: ENERO 2025 - REGISTRO DE MOVIMIENTOS
B2: INGRESOS | C2: MAURO | D2: DAIANA | E2: Total Ingresos
B5: # | C5: Persona | D5: Fecha | E5: Categoria | F5: Monto | G5: Forma de Pago | H5: Descripcion | I5: Etiqueta | J5: Notas
B6: =IF(C6<>"",ROW()-5,"") -> #ERROR!
B7: =IF(C7<>"",ROW()-5,"") -> #ERROR!
B8: =IF(C8<>"",ROW()-5,"") -> #ERROR!
B9: =IF(C9<>"",ROW()-5,"") -> #ERROR!
B10: =IF(C10<>"",ROW()-5,"") -> #ERROR!
B11: =IF(C11<>"",ROW()-5,"") -> #ERROR!
B12: =IF(C12<>"",ROW()-5,"") -> #ERROR!
B13: =IF(C13<>"",ROW()-5,"") -> #ERROR!
B14: =IF(C14<>"",ROW()-5,"") -> #ERROR!
B15: =IF(C15<>"",ROW()-5,"") -> #ERROR!
B16: =IF(C16<>"",ROW()-5,"") -> #ERROR!
B17: =IF(C17<>"",ROW()-5,"") -> #ERROR!
... B55: =IF(C55<>"",ROW()-5,"") -> #ERROR!
B56: TOTALES DEL MES | F56: =SUM(F6:F55) -> 0
B59: RESUMEN DEL MES
B60: Ingresos | D60: Gastos | F60: Balance | H60: Ahorro
B61: =E3 | D61: =SUM(F6:F55) -> 0 | F61: =E3-SUM(F6:F55) -> 0 | H61: =MAX(E3-SUM(F6:F55),0) -> #ERROR!
B63: POR PERSONA
D64: Ingresos | F64: Gastos | H64: Balance
B65: Franco | D65: =C3 | F65: =SUMIFS(F6:F55,C6:C55,"Franco") -> #ERROR! | H65: =D65-F65 -> #ERROR!
B66: Pareja | D66: =D3 | F66: =SUMIFS(F6:F55,C6:C55,"Pareja") -> #ERROR! | H66: =D66-F66 -> #ERROR!

Sheet Febrero
B1: FEBRERO 2025 - REGISTRO DE MOVIMIENTOS
B2: INGRESOS | C2: Franco | D2: Pareja | E2: Total Ingresos
E3: =C3+D3 -> 0
B5: # | C5: Persona | D5: Fecha | E5: Categoria | F5: Monto | G5: Forma de Pago | H5: Descripcion | I5: Etiqueta | J5: Notas
B6: =IF(C6<>"",ROW()-5,"") -> #ERROR!
B7: =IF(C7<>"",ROW()-5,"") -> #ERROR!
B8: =IF(C8<>"",ROW()-5,"") -> #ERROR!
B9: =IF(C9<>"",ROW()-5,"") -> #ERROR!
B10: =IF(C10<>"",ROW()-5,"") -> #ERROR!
B11: =IF(C11<>"",ROW()-5,"") -> #ERROR!
B12: =IF(C12<>"",ROW()-5,"") -> #ERROR!
B13: =IF(C13<>"",ROW()-5,"") -> #ERROR!
B14: =IF(C14<>"",ROW()-5,"") -> #ERROR!
B15: =IF(C15<>"",ROW()-5,"") -> #ERROR!
B16: =IF(C16<>"",ROW()-5,"") -> #ERROR!
B17: =IF(C17<>"",ROW()-5,"") -> #ERROR!
... B55: =IF(C55<>"",ROW()-5,"") -> #ERROR!
B56: TOTALES DEL MES | F56: =SUM(F6:F55) -> 0
B59: RESUMEN DEL MES
B60: Ingresos | D60: Gastos | F60: Balance | H60: Ahorro
B61: =E3 -> 0 | D61: =SUM(F6:F55) -> 0 | F61: =E3-SUM(F6:F55) -> 0 | H61: =MAX(E3-SUM(F6:F55),0) -> #ERROR!
B63: POR PERSONA
D64: Ingresos | F64: Gastos | H64: Balance
B65: Franco | D65: =C3 | F65: =SUMIFS(F6:F55,C6:C55,"Franco") -> #ERROR! | H65: =D65-F65 -> #ERROR!
B66: Pareja | D66: =D3 | F66: =SUMIFS(F6:F55,C6:C55,"Pareja") -> #ERROR! | H66: =D66-F66 -> #ERROR!

Sheet Marzo
B1: MARZO 2025 - REGISTRO DE MOVIMIENTOS
B2: INGRESOS | C2: Franco | D2: Pareja | E2: Total Ingresos
C3: 10000 | E3: =C3+D3 -> 10000
B5: # | C5: Persona | D5: Fecha | E5: Categoria | F5: Monto | G5: Forma de Pago | H5: Descripcion | I5: Etiqueta | J5: Notas
B6: =IF(C6<>"",ROW()-5,"") -> #ERROR!
B7: =IF(C7<>"",ROW()-5,"") -> #ERROR!
B8: =IF(C8<>"",ROW()-5,"") -> #ERROR!
B9: =IF(C9<>"",ROW()-5,"") -> #ERROR!
B10: =IF(C10<>"",ROW()-5,"") -> #ERROR!
B11: =IF(C11<>"",ROW()-5,"") -> #ERROR!
B12: =IF(C12<>"",ROW()-5,"") -> #ERROR!
B13: =IF(C13<>"",ROW()-5,"") -> #ERROR!
B14: =IF(C14<>"",ROW()-5,"") -> #ERROR!
B15: =IF(C15<>"",ROW()-5,"") -> #ERROR!
B16: =IF(C16<>"",ROW()-5,"") -> #ERROR!
B17: =IF(C17<>"",ROW()-5,"") -> #ERROR!
... B55: =IF(C55<>"",ROW()-5,"") -> #ERROR!
B56: TOTALES DEL MES | F56: =SUM(F6:F55) -> 0
B59: RESUMEN DEL MES
B60: Ingresos | D60: Gastos | F60: Balance | H60: Ahorro
B61: =E3 -> 10000 | D61: =SUM(F6:F55) -> 0 | F61: =E3-SUM(F6:F55) -> 10000 | H61: =MAX(E3-SUM(F6:F55),0) -> #ERROR!
B63: POR PERSONA
D64: Ingresos | F64: Gastos | H64: Balance
B65: Franco | D65: =C3 -> 10000 | F65: =SUMIFS(F6:F55,C6:C55,"Franco") -> #ERROR! | H65: =D65-F65 -> #ERROR!
B66: Pareja | D66: =D3 | F66: =SUMIFS(F6:F55,C6:C55,"Pareja") -> #ERROR! | H66: =D66-F66 -> #ERROR!

Sheet Abril
B1: ABRIL 2025 - REGISTRO DE MOVIMIENTOS
B2: INGRESOS | C2: Mauro | D2: Daiana | E2: Total Ingresos
D3: 6000000 | E3: =C3+D3 -> 6000000
B5: # | C5: Persona | D5: Fecha | E5: Categoria | F5: Monto | G5: Forma de Pago | H5: Descripcion | I5: Etiqueta | J5: Notas
B6: =IF(C6<>"",ROW()-5,"") -> #ERROR! | C6: DAIANA | D6: 46123 | E6: Vivienda | F6: 1200000 | G6: Efectivo | H6: Pago de alquiler | I6: Fijo
B7: =IF(C7<>"",ROW()-5,"") -> #ERROR! | C7: DAIANA | D7: 46118 | E7: Otros | F7: 685000 | G7: Transferencia | H7: Pago prestamo | I7: Fijo
B8: =IF(C8<>"",ROW()-5,"") -> #ERROR! | C8: DAIANA | D8: 46118 | E8: Otros | F8: 122000 | G8: Transferencia | H8: Pago por cosmeticos | I8: Variable
B9: =IF(C9<>"",ROW()-5,"") -> #ERROR! | C9: DAIANA | D9: 46118 | E9: Salud | F9: 540000 | G9: Tarjeta Débito | H9: IPS | I9: Fijo
B10: =IF(C10<>"",ROW()-5,"") -> #ERROR! | C10: DAIANA | D10: 46118 | E10: Otros | F10: 500000 | G10: Efectivo | H10: Quincena | I10: Fijo
B11: =IF(C11<>"",ROW()-5,"") -> #ERROR! | C11: DAIANA | D11: 46123 | E11: Ropa | F11: 200000 | G11: Efectivo | H11: Vestido | I11: Variable
B12: =IF(C12<>"",ROW()-5,"") -> #ERROR! | C12: DAIANA | D12: 46119 | E12: Alimentación | F12: 350000 | G12: Efectivo | H12: Comita (triangulo) | I12: Variable
B13: =IF(C13<>"",ROW()-5,"") -> #ERROR! | C13: DAIANA | D13: 46140 | E13: Vivienda | F13: 300000 | G13: Efectivo | H13: Luz | I13: Fijo
B14: =IF(C14<>"",ROW()-5,"") -> #ERROR! | C14: DAIANA | D14: 46140 | E14: Vivienda | F14: 100000 | G14: Efectivo | H14: Agua | I14: Fijo
B15: =IF(C15<>"",ROW()-5,"") -> #ERROR! | C15: DAIANA | D15: 46140 | E15: Vivienda | F15: 100000 | G15: Efectivo | H15: Basura | I15: Fijo
B16: =IF(C16<>"",ROW()-5,"") -> #ERROR! | C16: DAIANA | D16: 46118 | E16: Entretenimiento | F16: 600000 | G16: Tarjeta Débito | H16: Vale de compras LG | I16: Variable
B17: =IF(C17<>"",ROW()-5,"") -> #ERROR!
B18: =IF(C18<>"",ROW()-5,"") -> #ERROR!
B19: =IF(C19<>"",ROW()-5,"") -> #ERROR!
B20: =IF(C20<>"",ROW()-5,"") -> #ERROR!
B21: =IF(C21<>"",ROW()-5,"") -> #ERROR!
B22: =IF(C22<>"",ROW()-5,"") -> #ERROR!
B23: =IF(C23<>"",ROW()-5,"") -> #ERROR!
B24: =IF(C24<>"",ROW()-5,"") -> #ERROR!
B25: =IF(C25<>"",ROW()-5,"") -> #ERROR!
B26: =IF(C26<>"",ROW()-5,"") -> #ERROR!
B27: =IF(C27<>"",ROW()-5,"") -> #ERROR!
B28: =IF(C28<>"",ROW()-5,"") -> #ERROR!
... B55: =IF(C55<>"",ROW()-5,"") -> #ERROR!
B56: TOTALES DEL MES | F56: =SUM(F6:F55) -> 4697000
B59: RESUMEN DEL MES
B60: Ingresos | D60: Gastos | F60: Balance | H60: Ahorro
B61: =E3 -> 6000000 | D61: =SUM(F6:F55) -> 4697000 | F61: =E3-SUM(F6:F55) -> 1303000 | H61: =MAX(E3-SUM(F6:F55),0) -> #ERROR!
B63: POR PERSONA
D64: Ingresos | F64: Gastos | H64: Balance
B65: Franco | D65: =C3 | F65: =SUMIFS(F6:F55,C6:C55,"Franco") -> #ERROR! | H65: =D65-F65 -> #ERROR!
B66: Pareja | D66: =D3 -> 6000000 | F66: =SUMIFS(F6:F55,C6:C55,"Pareja") -> #ERROR! | H66: =D66-F66 -> #ERROR!

Sheet Mayo
B1: MAYO 2025 - REGISTRO DE MOVIMIENTOS
B2: INGRESOS | C2: Franco | D2: Pareja | E2: Total Ingresos
E3: =C3+D3 -> 0
B5: # | C5: Persona | D5: Fecha | E5: Categoria | F5: Monto | G5: Forma de Pago | H5: Descripcion | I5: Etiqueta | J5: Notas
B6: =IF(C6<>"",ROW()-5,"") -> #ERROR!
B7: =IF(C7<>"",ROW()-5,"") -> #ERROR!
B8: =IF(C8<>"",ROW()-5,"") -> #ERROR!
B9: =IF(C9<>"",ROW()-5,"") -> #ERROR!
B10: =IF(C10<>"",ROW()-5,"") -> #ERROR!
B11: =IF(C11<>"",ROW()-5,"") -> #ERROR!
B12: =IF(C12<>"",ROW()-5,"") -> #ERROR!
B13: =IF(C13<>"",ROW()-5,"") -> #ERROR!
B14: =IF(C14<>"",ROW()-5,"") -> #ERROR!
B15: =IF(C15<>"",ROW()-5,"") -> #ERROR!
B16: =IF(C16<>"",ROW()-5,"") -> #ERROR!
B17: =IF(C17<>"",ROW()-5,"") -> #ERROR!
... B55: =IF(C55<>"",ROW()-5,"") -> #ERROR!
B56: TOTALES DEL MES | F56: =SUM(F6:F55) -> 0
B59: RESUMEN DEL MES
B60: Ingresos | D60: Gastos | F60: Balance | H60: Ahorro
B61: =E3 -> 0 | D61: =SUM(F6:F55) -> 0 | F61: =E3-SUM(F6:F55) -> 0 | H61: =MAX(E3-SUM(F6:F55),0) -> #ERROR!
B63: POR PERSONA
D64: Ingresos | F64: Gastos | H64: Balance
B65: Franco | D65: =C3 | F65: =SUMIFS(F6:F55,C6:C55,"Franco") -> #ERROR! | H65: =D65-F65 -> #ERROR!
B66: Pareja | D66: =D3 | F66: =SUMIFS(F6:F55,C6:C55,"Pareja") -> #ERROR! | H66: =D66-F66 -> #ERROR!

Sheet Junio
B1: JUNIO 2025 - REGISTRO DE MOVIMIENTOS
B2: INGRESOS | C2: Franco | D2: Pareja | E2: Total Ingresos
E3: =C3+D3 -> 0
B5: # | C5: Persona | D5: Fecha | E5: Categoria | F5: Monto | G5: Forma de Pago | H5: Descripcion | I5: Etiqueta | J5: Notas
B6: =IF(C6<>"",ROW()-5,"") -> #ERROR!
B7: =IF(C7<>"",ROW()-5,"") -> #ERROR!
B8: =IF(C8<>"",ROW()-5,"") -> #ERROR!
B9: =IF(C9<>"",ROW()-5,"") -> #ERROR!
B10: =IF(C10<>"",ROW()-5,"") -> #ERROR!
B11: =IF(C11<>"",ROW()-5,"") -> #ERROR!
B12: =IF(C12<>"",ROW()-5,"") -> #ERROR!
B13: =IF(C13<>"",ROW()-5,"") -> #ERROR!
B14: =IF(C14<>"",ROW()-5,"") -> #ERROR!
B15: =IF(C15<>"",ROW()-5,"") -> #ERROR!
B16: =IF(C16<>"",ROW()-5,"") -> #ERROR!
B17: =IF(C17<>"",ROW()-5,"") -> #ERROR!
... B55: =IF(C55<>"",ROW()-5,"") -> #ERROR!
B56: TOTALES DEL MES | F56: =SUM(F6:F55) -> 0
B59: RESUMEN DEL MES
B60: Ingresos | D60: Gastos | F60: Balance | H60: Ahorro
B61: =E3 -> 0 | D61: =SUM(F6:F55) -> 0 | F61: =E3-SUM(F6:F55) -> 0 | H61: =MAX(E3-SUM(F6:F55),0) -> #ERROR!
B63: POR PERSONA
D64: Ingresos | F64: Gastos | H64: Balance
B65: Franco | D65: =C3 | F65: =SUMIFS(F6:F55,C6:C55,"Franco") -> #ERROR! | H65: =D65-F65 -> #ERROR!
B66: Pareja | D66: =D3 | F66: =SUMIFS(F6:F55,C6:C55,"Pareja") -> #ERROR! | H66: =D66-F66 -> #ERROR!

Sheet Julio
B1: JULIO 2025 - REGISTRO DE MOVIMIENTOS
B2: INGRESOS | C2: Franco | D2: Pareja | E2: Total Ingresos
E3: =C3+D3 -> 0
B5: # | C5: Persona | D5: Fecha | E5: Categoria | F5: Monto | G5: Forma de Pago | H5: Descripcion | I5: Etiqueta | J5: Notas
B6: =IF(C6<>"",ROW()-5,"") -> #ERROR!
B7: =IF(C7<>"",ROW()-5,"") -> #ERROR!
B8: =IF(C8<>"",ROW()-5,"") -> #ERROR!
B9: =IF(C9<>"",ROW()-5,"") -> #ERROR!
B10: =IF(C10<>"",ROW()-5,"") -> #ERROR!
B11: =IF(C11<>"",ROW()-5,"") -> #ERROR!
B12: =IF(C12<>"",ROW()-5,"") -> #ERROR!
B13: =IF(C13<>"",ROW()-5,"") -> #ERROR!
B14: =IF(C14<>"",ROW()-5,"") -> #ERROR!
B15: =IF(C15<>"",ROW()-5,"") -> #ERROR!
B16: =IF(C16<>"",ROW()-5,"") -> #ERROR!
B17: =IF(C17<>"",ROW()-5,"") -> #ERROR!
... B55: =IF(C55<>"",ROW()-5,"") -> #ERROR!
B56: TOTALES DEL MES | F56: =SUM(F6:F55) -> 0
B59: RESUMEN DEL MES
B60: Ingresos | D60: Gastos | F60: Balance | H60: Ahorro
B61: =E3 -> 0 | D61: =SUM(F6:F55) -> 0 | F61: =E3-SUM(F6:F55) -> 0 | H61: =MAX(E3-SUM(F6:F55),0) -> #ERROR!
B63: POR PERSONA
D64: Ingresos | F64: Gastos | H64: Balance
B65: Franco | D65: =C3 | F65: =SUMIFS(F6:F55,C6:C55,"Franco") -> #ERROR! | H65: =D65-F65 -> #ERROR!
B66: Pareja | D66: =D3 | F66: =SUMIFS(F6:F55,C6:C55,"Pareja") -> #ERROR! | H66: =D66-F66 -> #ERROR!

Sheet Agosto
B1: AGOSTO 2025 - REGISTRO DE MOVIMIENTOS
B2: INGRESOS | C2: Franco | D2: Pareja | E2: Total Ingresos
E3: =C3+D3 -> 0
B5: # | C5: Persona | D5: Fecha | E5: Categoria | F5: Monto | G5: Forma de Pago | H5: Descripcion | I5: Etiqueta | J5: Notas
B6: =IF(C6<>"",ROW()-5,"") -> #ERROR!
B7: =IF(C7<>"",ROW()-5,"") -> #ERROR!
B8: =IF(C8<>"",ROW()-5,"") -> #ERROR!
B9: =IF(C9<>"",ROW()-5,"") -> #ERROR!
B10: =IF(C10<>"",ROW()-5,"") -> #ERROR!
B11: =IF(C11<>"",ROW()-5,"") -> #ERROR!
B12: =IF(C12<>"",ROW()-5,"") -> #ERROR!
B13: =IF(C13<>"",ROW()-5,"") -> #ERROR!
B14: =IF(C14<>"",ROW()-5,"") -> #ERROR!
B15: =IF(C15<>"",ROW()-5,"") -> #ERROR!
B16: =IF(C16<>"",ROW()-5,"") -> #ERROR!
B17: =IF(C17<>"",ROW()-5,"") -> #ERROR!
... B55: =IF(C55<>"",ROW()-5,"") -> #ERROR!
B56: TOTALES DEL MES | F56: =SUM(F6:F55) -> 0
B59: RESUMEN DEL MES
B60: Ingresos | D60: Gastos | F60: Balance | H60: Ahorro
B61: =E3 -> 0 | D61: =SUM(F6:F55) -> 0 | F61: =E3-SUM(F6:F55) -> 0 | H61: =MAX(E3-SUM(F6:F55),0) -> #ERROR!
B63: POR PERSONA
D64: Ingresos | F64: Gastos | H64: Balance
B65: Franco | D65: =C3 | F65: =SUMIFS(F6:F55,C6:C55,"Franco") -> #ERROR! | H65: =D65-F65 -> #ERROR!
B66: Pareja | D66: =D3 | F66: =SUMIFS(F6:F55,C6:C55,"Pareja") -> #ERROR! | H66: =D66-F66 -> #ERROR!

Sheet Septiembre
B1: SEPTIEMBRE 2025 - REGISTRO DE MOVIMIENTOS
B2: INGRESOS | C2: Franco | D2: Pareja | E2: Total Ingresos
E3: =C3+D3 -> 0
B5: # | C5: Persona | D5: Fecha | E5: Categoria | F5: Monto | G5: Forma de Pago | H5: Descripcion | I5: Etiqueta | J5: Notas
B6: =IF(C6<>"",ROW()-5,"") -> #ERROR!
B7: =IF(C7<>"",ROW()-5,"") -> #ERROR!
B8: =IF(C8<>"",ROW()-5,"") -> #ERROR!
B9: =IF(C9<>"",ROW()-5,"") -> #ERROR!
B10: =IF(C10<>"",ROW()-5,"") -> #ERROR!
B11: =IF(C11<>"",ROW()-5,"") -> #ERROR!
B12: =IF(C12<>"",ROW()-5,"") -> #ERROR!
B13: =IF(C13<>"",ROW()-5,"") -> #ERROR!
B14: =IF(C14<>"",ROW()-5,"") -> #ERROR!
B15: =IF(C15<>"",ROW()-5,"") -> #ERROR!
B16: =IF(C16<>"",ROW()-5,"") -> #ERROR!
B17: =IF(C17<>"",ROW()-5,"") -> #ERROR!
... B55: =IF(C55<>"",ROW()-5,"") -> #ERROR!
B56: TOTALES DEL MES | F56: =SUM(F6:F55) -> 0
B59: RESUMEN DEL MES
B60: Ingresos | D60: Gastos | F60: Balance | H60: Ahorro
B61: =E3 -> 0 | D61: =SUM(F6:F55) -> 0 | F61: =E3-SUM(F6:F55) -> 0 | H61: =MAX(E3-SUM(F6:F55),0) -> #ERROR!
B63: POR PERSONA
D64: Ingresos | F64: Gastos | H64: Balance
B65: Franco | D65: =C3 | F65: =SUMIFS(F6:F55,C6:C55,"Franco") -> #ERROR! | H65: =D65-F65 -> #ERROR!
B66: Pareja | D66: =D3 | F66: =SUMIFS(F6:F55,C6:C55,"Pareja") -> #ERROR! | H66: =D66-F66 -> #ERROR!

Sheet Octubre
B1: OCTUBRE 2025 - REGISTRO DE MOVIMIENTOS
B2: INGRESOS | C2: Franco | D2: Pareja | E2: Total Ingresos
E3: =C3+D3 -> 0
B5: # | C5: Persona | D5: Fecha | E5: Categoria | F5: Monto | G5: Forma de Pago | H5: Descripcion | I5: Etiqueta | J5: Notas
B6: =IF(C6<>"",ROW()-5,"") -> #ERROR!
B7: =IF(C7<>"",ROW()-5,"") -> #ERROR!
B8: =IF(C8<>"",ROW()-5,"") -> #ERROR!
B9: =IF(C9<>"",ROW()-5,"") -> #ERROR!
B10: =IF(C10<>"",ROW()-5,"") -> #ERROR!
B11: =IF(C11<>"",ROW()-5,"") -> #ERROR!
B12: =IF(C12<>"",ROW()-5,"") -> #ERROR!
B13: =IF(C13<>"",ROW()-5,"") -> #ERROR!
B14: =IF(C14<>"",ROW()-5,"") -> #ERROR!
B15: =IF(C15<>"",ROW()-5,"") -> #ERROR!
B16: =IF(C16<>"",ROW()-5,"") -> #ERROR!
B17: =IF(C17<>"",ROW()-5,"") -> #ERROR!
... B55: =IF(C55<>"",ROW()-5,"") -> #ERROR!
B56: TOTALES DEL MES | F56: =SUM(F6:F55) -> 0
